<?xml version="1.0" ?>
<robot name="no">

<material name="silver">
  <color rgba="0.700 0.700 0.700 1.000"/>
</material>

<link name="base_link">
  <inertial>
    <origin rpy="0 0 0" xyz="0.04921698329927212 -0.05604060081261414 0.0096411184071391"/>
    <mass value="6.458470839830133"/>
    <inertia ixx="0.020052754695234584" ixy="-0.00013298652567026586" ixz="-8.027298909880649e-06" iyy="0.03313333073146825" iyz="0.002939393812051047" izz="0.037093687043066974"/>
  </inertial>
  <visual>
    <origin rpy="0 0 0" xyz="0 0 0"/>
    <geometry>
      <mesh filename="meshes/base_link.stl" scale="0.001 0.001 0.001"/>
    </geometry>
    <material name="silver"/>
    <material/>
  </visual>
  <collision>
    <origin rpy="0 0 0" xyz="0 0 0"/>
    <geometry>
      <mesh filename="meshes/base_link.stl" scale="0.001 0.001 0.001"/>
    </geometry>
  </collision>
</link>

<link name="servo_v11">
  <inertial>
    <origin rpy="0 0 0" xyz="0.005870140924492633 0.008916408973558831 -0.024601570180154596"/>
    <mass value="0.25257832542625036"/>
    <inertia ixx="6.81815359492681e-05" ixy="2.7633792335553936e-12" ixz="4.3931222885931754e-11" iyy="4.4096030150315126e-05" iyz="-5.05518336747909e-07" izz="4.0626755970178154e-05"/>
  </inertial>
  <visual>
    <origin rpy="0 0 0" xyz="0.006829 0.137658 -0.035397"/>
    <geometry>
      <mesh filename="meshes/servo_v11.stl" scale="0.001 0.001 0.001"/>
    </geometry>
    <material name="silver"/>
    <material/>
  </visual>
  <collision>
    <origin rpy="0 0 0" xyz="0.006829 0.137658 -0.035397"/>
    <geometry>
      <mesh filename="meshes/servo_v11.stl" scale="0.001 0.001 0.001"/>
    </geometry>
  </collision>
</link>

<link name="servo_v1_11">
  <inertial>
    <origin rpy="0 0 0" xyz="-0.005874859075507569 0.008916411148642306 -0.02460157018015461"/>
    <mass value="0.25257832542625036"/>
    <inertia ixx="6.81815359492681e-05" ixy="2.763379802761534e-12" ixz="4.393122291727197e-11" iyy="4.409603015031495e-05" iyz="-5.055183367479632e-07" izz="4.0626755970177286e-05"/>
  </inertial>
  <visual>
    <origin rpy="0 0 0" xyz="-0.104916 0.137658 -0.035397"/>
    <geometry>
      <mesh filename="meshes/servo_v1_11.stl" scale="0.001 0.001 0.001"/>
    </geometry>
    <material name="silver"/>
    <material/>
  </visual>
  <collision>
    <origin rpy="0 0 0" xyz="-0.104916 0.137658 -0.035397"/>
    <geometry>
      <mesh filename="meshes/servo_v1_11.stl" scale="0.001 0.001 0.001"/>
    </geometry>
  </collision>
</link>

<link name="darwin_SP0-5_Dfaut_v1_11">
  <inertial>
    <origin rpy="0 0 0" xyz="1.1286443875324625e-07 0.0014997351662959513 3.8904902076850913e-07"/>
    <mass value="0.00403268334001312"/>
    <inertia ixx="9.404135631033335e-08" ixy="-6.776263578034403e-21" ixz="2.117582368135751e-22" iyy="1.8171957172164268e-07" iyz="1.7745340244977592e-19" izz="9.404135767061405e-08"/>
  </inertial>
  <visual>
    <origin rpy="0 0 0" xyz="-0.099041 0.153968 -0.000819"/>
    <geometry>
      <mesh filename="meshes/darwin_SP0-5_Dfaut_v1_11.stl" scale="0.001 0.001 0.001"/>
    </geometry>
    <material name="silver"/>
    <material/>
  </visual>
  <collision>
    <origin rpy="0 0 0" xyz="-0.099041 0.153968 -0.000819"/>
    <geometry>
      <mesh filename="meshes/darwin_SP0-5_Dfaut_v1_11.stl" scale="0.001 0.001 0.001"/>
    </geometry>
  </collision>
</link>

<link name="darwin_SP0-5_Dfaut_v11">
  <inertial>
    <origin rpy="0 0 0" xyz="1.1286443896488252e-07 0.0014997329912125323 3.8904902078629004e-07"/>
    <mass value="0.00403268334001312"/>
    <inertia ixx="9.404135631030624e-08" ixy="2.117582368135751e-22" ixz="1.7453510924868884e-22" iyy="1.8171957172164205e-07" iyz="1.7724164421296235e-19" izz="9.404135767058694e-08"/>
  </inertial>
  <visual>
    <origin rpy="0 0 0" xyz="0.000959 0.153968 -0.000819"/>
    <geometry>
      <mesh filename="meshes/darwin_SP0-5_Dfaut_v11.stl" scale="0.001 0.001 0.001"/>
    </geometry>
    <material name="silver"/>
    <material/>
  </visual>
  <collision>
    <origin rpy="0 0 0" xyz="0.000959 0.153968 -0.000819"/>
    <geometry>
      <mesh filename="meshes/darwin_SP0-5_Dfaut_v11.stl" scale="0.001 0.001 0.001"/>
    </geometry>
  </collision>
</link>

<link name="puru_returns_Component6_v31">
  <inertial>
    <origin rpy="0 0 0" xyz="-0.005999887135591233 -0.012239052753954482 -0.018406472236115055"/>
    <mass value="0.04702613835521159"/>
    <inertia ixx="4.9731123091805536e-05" ixy="-1.912176878426583e-17" ixz="1.0964841502206918e-17" iyy="4.3118777716014306e-05" iyz="1.9201203024806325e-06" izz="9.510411171800718e-06"/>
  </inertial>
  <visual>
    <origin rpy="0 0 0" xyz="-0.005041 0.153968 -0.000819"/>
    <geometry>
      <mesh filename="meshes/puru_returns_Component6_v31.stl" scale="0.001 0.001 0.001"/>
    </geometry>
    <material name="silver"/>
    <material/>
  </visual>
  <collision>
    <origin rpy="0 0 0" xyz="-0.005041 0.153968 -0.000819"/>
    <geometry>
      <mesh filename="meshes/puru_returns_Component6_v31.stl" scale="0.001 0.001 0.001"/>
    </geometry>
  </collision>
</link>

<link name="puru_returns_Component6_v3_11">
  <inertial>
    <origin rpy="0 0 0" xyz="-0.005999887135591436 -0.012239050578871119 -0.018406472236115076"/>
    <mass value="0.04702613835521159"/>
    <inertia ixx="4.9731123091805536e-05" ixy="-1.929879867024198e-17" ixz="1.0923336887791457e-17" iyy="4.311877771601423e-05" iyz="1.9201203024806325e-06" izz="9.510411171800284e-06"/>
  </inertial>
  <visual>
    <origin rpy="0 0 0" xyz="-0.105041 0.153968 -0.000819"/>
    <geometry>
      <mesh filename="meshes/puru_returns_Component6_v3_11.stl" scale="0.001 0.001 0.001"/>
    </geometry>
    <material name="silver"/>
    <material/>
  </visual>
  <collision>
    <origin rpy="0 0 0" xyz="-0.105041 0.153968 -0.000819"/>
    <geometry>
      <mesh filename="meshes/puru_returns_Component6_v3_11.stl" scale="0.001 0.001 0.001"/>
    </geometry>
  </collision>
</link>

<link name="darwin_SP0-5_Dfaut_v1_21">
  <inertial>
    <origin rpy="0 0 0" xyz="-0.0059998871355610535 2.3379328095707308e-07 0.0014995640075279523"/>
    <mass value="0.00403268334001312"/>
    <inertia ixx="9.404135631029269e-08" ixy="-1.0587911840678754e-22" ixz="2.6469779601696886e-23" iyy="9.404135767058694e-08" iyz="-1.6940658945086007e-19" izz="1.8171957172160203e-07"/>
  </inertial>
  <visual>
    <origin rpy="0 0 0" xyz="-0.005041 0.1896 0.055254"/>
    <geometry>
      <mesh filename="meshes/darwin_SP0-5_Dfaut_v1_21.stl" scale="0.001 0.001 0.001"/>
    </geometry>
    <material name="silver"/>
    <material/>
  </visual>
  <collision>
    <origin rpy="0 0 0" xyz="-0.005041 0.1896 0.055254"/>
    <geometry>
      <mesh filename="meshes/darwin_SP0-5_Dfaut_v1_21.stl" scale="0.001 0.001 0.001"/>
    </geometry>
  </collision>
</link>

<link name="servo_v1_21">
  <inertial>
    <origin rpy="0 0 0" xyz="-0.009016927906611374 -0.052254794266546806 0.2150762399898742"/>
    <mass value="0.25257832542625036"/>
    <inertia ixx="4.0626755970177286e-05" ixy="4.3931222808851755e-11" ixz="5.055183367479903e-07" iyy="6.818153594926848e-05" iyz="-2.763379369080665e-12" izz="4.4096030150313215e-05"/>
  </inertial>
  <visual>
    <origin rpy="0 0 0" xyz="0.001918 0.137345 0.243354"/>
    <geometry>
      <mesh filename="meshes/servo_v1_21.stl" scale="0.001 0.001 0.001"/>
    </geometry>
    <material name="silver"/>
    <material/>
  </visual>
  <collision>
    <origin rpy="0 0 0" xyz="0.001918 0.137345 0.243354"/>
    <geometry>
      <mesh filename="meshes/servo_v1_21.stl" scale="0.001 0.001 0.001"/>
    </geometry>
  </collision>
</link>

<link name="darwin_SP0-5_Dfaut_v1_31">
  <inertial>
    <origin rpy="0 0 0" xyz="-0.005999887135561197 2.359683643204935e-07 0.0014995640075279593"/>
    <mass value="0.00403268334001312"/>
    <inertia ixx="9.404135631026558e-08" ixy="1.3552527156068805e-20" ixz="-3.3881317890172014e-21" iyy="9.404135767059372e-08" iyz="-1.7618285302889447e-19" izz="1.8171957172160203e-07"/>
  </inertial>
  <visual>
    <origin rpy="0 0 0" xyz="-0.105041 0.1896 0.055254"/>
    <geometry>
      <mesh filename="meshes/darwin_SP0-5_Dfaut_v1_31.stl" scale="0.001 0.001 0.001"/>
    </geometry>
    <material name="silver"/>
    <material/>
  </visual>
  <collision>
    <origin rpy="0 0 0" xyz="-0.105041 0.1896 0.055254"/>
    <geometry>
      <mesh filename="meshes/darwin_SP0-5_Dfaut_v1_31.stl" scale="0.001 0.001 0.001"/>
    </geometry>
  </collision>
</link>

<link name="servo_v1_31">
  <inertial>
    <origin rpy="0 0 0" xyz="-0.08906484636451088 -0.052254735971356187 0.21332623998987424"/>
    <mass value="0.25257832542625036"/>
    <inertia ixx="4.062675597017902e-05" ixy="4.3931223242532624e-11" ixz="-5.05518336747909e-07" iyy="6.818153594926853e-05" iyz="2.763378935399796e-12" izz="4.4096030150316684e-05"/>
  </inertial>
  <visual>
    <origin rpy="0 0 0" xyz="-0.198082 0.137345 0.243354"/>
    <geometry>
      <mesh filename="meshes/servo_v1_31.stl" scale="0.001 0.001 0.001"/>
    </geometry>
    <material name="silver"/>
    <material/>
  </visual>
  <collision>
    <origin rpy="0 0 0" xyz="-0.198082 0.137345 0.243354"/>
    <geometry>
      <mesh filename="meshes/servo_v1_31.stl" scale="0.001 0.001 0.001"/>
    </geometry>
  </collision>
</link>

<link name="New_comp_v31">
  <inertial>
    <origin rpy="0 0 0" xyz="0.027128095790387684 -0.007395019778211831 0.02515028782657007"/>
    <mass value="0.09272661140293506"/>
    <inertia ixx="5.0412790144149875e-05" ixy="1.3253400060312694e-06" ixz="-5.403142625515365e-06" iyy="5.750978567617084e-05" iyz="1.033012533412561e-05" izz="4.581305763172103e-05"/>
  </inertial>
  <visual>
    <origin rpy="0 0 0" xyz="0.035537 0.18373 0.037194"/>
    <geometry>
      <mesh filename="meshes/New_comp_v31.stl" scale="0.001 0.001 0.001"/>
    </geometry>
    <material name="silver"/>
    <material/>
  </visual>
  <collision>
    <origin rpy="0 0 0" xyz="0.035537 0.18373 0.037194"/>
    <geometry>
      <mesh filename="meshes/New_comp_v31.stl" scale="0.001 0.001 0.001"/>
    </geometry>
  </collision>
</link>

<link name="servo_v1_41">
  <inertial>
    <origin rpy="0 0 0" xyz="0.008916774183236064 -0.024198736400501353 -0.005870309547772342"/>
    <mass value="0.25257832542625036"/>
    <inertia ixx="4.409603015031495e-05" ixy="5.055183367480174e-07" ixz="-2.7633792648956127e-12" iyy="4.0626755970177544e-05" iyz="4.393122244293352e-11" izz="6.818153594926636e-05"/>
  </inertial>
  <visual>
    <origin rpy="0 0 0" xyz="0.017844 0.175379 -0.007851"/>
    <geometry>
      <mesh filename="meshes/servo_v1_41.stl" scale="0.001 0.001 0.001"/>
    </geometry>
    <material name="silver"/>
    <material/>
  </visual>
  <collision>
    <origin rpy="0 0 0" xyz="0.017844 0.175379 -0.007851"/>
    <geometry>
      <mesh filename="meshes/servo_v1_41.stl" scale="0.001 0.001 0.001"/>
    </geometry>
  </collision>
</link>

<link name="darwin_SP0-5_Dfaut_v1_41">
  <inertial>
    <origin rpy="0 0 0" xyz="-0.013410901799110097 -0.023975695629450705 -0.1896012814874929"/>
    <mass value="0.00403268334001312"/>
    <inertia ixx="1.8171957172162913e-07" ixy="0.0" ixz="-1.7718870465375895e-19" iyy="9.404135631031302e-08" iyz="0.0" izz="9.404135767061405e-08"/>
  </inertial>
  <visual>
    <origin rpy="0 0 0" xyz="0.018243 0.165626 -0.191582"/>
    <geometry>
      <mesh filename="meshes/darwin_SP0-5_Dfaut_v1_41.stl" scale="0.001 0.001 0.001"/>
    </geometry>
    <material name="silver"/>
    <material/>
  </visual>
  <collision>
    <origin rpy="0 0 0" xyz="0.018243 0.165626 -0.191582"/>
    <geometry>
      <mesh filename="meshes/darwin_SP0-5_Dfaut_v1_41.stl" scale="0.001 0.001 0.001"/>
    </geometry>
  </collision>
</link>

<link name="New_Component_v21Component171">
  <inertial>
    <origin rpy="0 0 0" xyz="0.022247272558917716 -0.052249658789782605 0.005981322131186955"/>
    <mass value="0.12057690606604259"/>
    <inertia ixx="9.059967566988052e-05" ixy="-3.367558764953249e-07" ixz="5.0605938449058895e-11" iyy="5.508347042585907e-05" iyz="-1.2191716247741556e-07" izz="0.00013649747999073484"/>
  </inertial>
  <visual>
    <origin rpy="0 0 0" xyz="0.033154 0.189602 0.004019"/>
    <geometry>
      <mesh filename="meshes/New_Component_v21Component171.stl" scale="0.001 0.001 0.001"/>
    </geometry>
    <material name="silver"/>
    <material/>
  </visual>
  <collision>
    <origin rpy="0 0 0" xyz="0.033154 0.189602 0.004019"/>
    <geometry>
      <mesh filename="meshes/New_Component_v21Component171.stl" scale="0.001 0.001 0.001"/>
    </geometry>
  </collision>
</link>

<link name="darwin_SP0-5_Dfaut_v1_51">
  <inertial>
    <origin rpy="0 0 0" xyz="-0.36413490179911173 0.023060715613680727 -0.03315346180666712"/>
    <mass value="0.00403268334001312"/>
    <inertia ixx="1.8171957172168334e-07" ixy="1.7618285302889447e-19" ixz="1.0587911840678754e-22" iyy="9.404135767058864e-08" iyz="-4.235164736271502e-22" izz="9.40413563103198e-08"/>
  </inertial>
  <visual>
    <origin rpy="0 0 0" xyz="-0.332481 0.322471 -0.035093"/>
    <geometry>
      <mesh filename="meshes/darwin_SP0-5_Dfaut_v1_51.stl" scale="0.001 0.001 0.001"/>
    </geometry>
    <material name="silver"/>
    <material/>
  </visual>
  <collision>
    <origin rpy="0 0 0" xyz="-0.332481 0.322471 -0.035093"/>
    <geometry>
      <mesh filename="meshes/darwin_SP0-5_Dfaut_v1_51.stl" scale="0.001 0.001 0.001"/>
    </geometry>
  </collision>
</link>

<link name="servo_v1_51">
  <inertial>
    <origin rpy="0 0 0" xyz="-0.2756832258167656 -0.008036325157144364 0.030153510133279087"/>
    <mass value="0.25257832542625036"/>
    <inertia ixx="4.4096030150320153e-05" ixy="5.05518336747909e-07" ixz="-2.7633792648956127e-12" iyy="4.062675597017746e-05" iyz="4.393122240227594e-11" izz="6.818153594927157e-05"/>
  </inertial>
  <visual>
    <origin rpy="0 0 0" xyz="-0.267756 0.30135 0.028214"/>
    <geometry>
      <mesh filename="meshes/servo_v1_51.stl" scale="0.001 0.001 0.001"/>
    </geometry>
    <material name="silver"/>
    <material/>
  </visual>
  <collision>
    <origin rpy="0 0 0" xyz="-0.267756 0.30135 0.028214"/>
    <geometry>
      <mesh filename="meshes/servo_v1_51.stl" scale="0.001 0.001 0.001"/>
    </geometry>
  </collision>
</link>

<link name="puru_returns_Component3_Copy_v11">
  <inertial>
    <origin rpy="0 0 0" xyz="0.01123524320427995 -0.05805215731289315 -0.004672109026543048"/>
    <mass value="0.18510629044043106"/>
    <inertia ixx="0.00012398617807459975" ixy="-1.4689737333858054e-05" ixz="-8.602094731073599e-07" iyy="5.902327368141696e-05" iyz="-7.755929246309887e-06" izz="0.0001667725633965854"/>
  </inertial>
  <visual>
    <origin rpy="0 0 0" xyz="0.016844 0.285188 -0.00781"/>
    <geometry>
      <mesh filename="meshes/puru_returns_Component3_Copy_v11.stl" scale="0.001 0.001 0.001"/>
    </geometry>
    <material name="silver"/>
    <material/>
  </visual>
  <collision>
    <origin rpy="0 0 0" xyz="0.016844 0.285188 -0.00781"/>
    <geometry>
      <mesh filename="meshes/puru_returns_Component3_Copy_v11.stl" scale="0.001 0.001 0.001"/>
    </geometry>
  </collision>
</link>

<link name="darwin_SP0-5_Dfaut_v1_61">
  <inertial>
    <origin rpy="0 0 0" xyz="0.00150036978879637 -0.006000284386093679 -4.6180644321471877e-07"/>
    <mass value="0.00403268334001312"/>
    <inertia ixx="1.8171957172157492e-07" ixy="6.776263578034403e-21" ixz="-1.7724164421296235e-19" iyy="9.404135631031386e-08" iyz="0.0" izz="9.404135767050563e-08"/>
  </inertial>
  <visual>
    <origin rpy="0 0 0" xyz="0.0327 0.40341 -0.00194"/>
    <geometry>
      <mesh filename="meshes/darwin_SP0-5_Dfaut_v1_61.stl" scale="0.001 0.001 0.001"/>
    </geometry>
    <material name="silver"/>
    <material/>
  </visual>
  <collision>
    <origin rpy="0 0 0" xyz="0.0327 0.40341 -0.00194"/>
    <geometry>
      <mesh filename="meshes/darwin_SP0-5_Dfaut_v1_61.stl" scale="0.001 0.001 0.001"/>
    </geometry>
  </collision>
</link>

<link name="servo_v1_61">
  <inertial>
    <origin rpy="0 0 0" xyz="-0.3856839542288572 0.039675756384956795 -0.0019394337466150382"/>
    <mass value="0.25257832542625036"/>
    <inertia ixx="4.4096030150313215e-05" ixy="-5.055183367480174e-07" ixz="2.76337921957935e-12" iyy="4.0626755970177544e-05" iyz="4.393122245648605e-11" izz="6.818153594926463e-05"/>
  </inertial>
  <visual>
    <origin rpy="0 0 0" xyz="-0.378211 0.43911 -0.003879"/>
    <geometry>
      <mesh filename="meshes/servo_v1_61.stl" scale="0.001 0.001 0.001"/>
    </geometry>
    <material name="silver"/>
    <material/>
  </visual>
  <collision>
    <origin rpy="0 0 0" xyz="-0.378211 0.43911 -0.003879"/>
    <geometry>
      <mesh filename="meshes/servo_v1_61.stl" scale="0.001 0.001 0.001"/>
    </geometry>
  </collision>
</link>

<link name="darwin_SP0-5_Dfaut_v1_71">
  <inertial>
    <origin rpy="0 0 0" xyz="0.00038936978879608973 0.04206000083428929 -0.4279644618066693"/>
    <mass value="0.00403268334001312"/>
    <inertia ixx="9.4041356310374e-08" ixy="0.0" ixz="1.3234889800848443e-21" iyy="9.404135767058747e-08" iyz="-1.7957098481791167e-19" izz="1.8171957172179176e-07"/>
  </inertial>
  <visual>
    <origin rpy="0 0 0" xyz="0.006779 0.451281 -0.415404"/>
    <geometry>
      <mesh filename="meshes/darwin_SP0-5_Dfaut_v1_71.stl" scale="0.001 0.001 0.001"/>
    </geometry>
    <material name="silver"/>
    <material/>
  </visual>
  <collision>
    <origin rpy="0 0 0" xyz="0.006779 0.451281 -0.415404"/>
    <geometry>
      <mesh filename="meshes/darwin_SP0-5_Dfaut_v1_71.stl" scale="0.001 0.001 0.001"/>
    </geometry>
  </collision>
</link>

<link name="servo_v1_71">
  <inertial>
    <origin rpy="0 0 0" xyz="0.01636541055984569 0.014059972774009943 -0.4329481377890159"/>
    <mass value="0.25257832542625036"/>
    <inertia ixx="4.0626755970177286e-05" ixy="-4.3931222429380995e-11" ixz="5.055183367480987e-07" iyy="6.818153594926864e-05" iyz="2.763379802761534e-12" izz="4.4096030150320153e-05"/>
  </inertial>
  <visual>
    <origin rpy="0 0 0" xyz="0.012779 0.423281 -0.396661"/>
    <geometry>
      <mesh filename="meshes/servo_v1_71.stl" scale="0.001 0.001 0.001"/>
    </geometry>
    <material name="silver"/>
    <material/>
  </visual>
  <collision>
    <origin rpy="0 0 0" xyz="0.012779 0.423281 -0.396661"/>
    <geometry>
      <mesh filename="meshes/servo_v1_71.stl" scale="0.001 0.001 0.001"/>
    </geometry>
  </collision>
</link>

<link name="puru_returns_Component1_v21">
  <inertial>
    <origin rpy="0 0 0" xyz="0.01964061064926636 -0.029622903107123844 0.008675672478626585"/>
    <mass value="0.3521119210080813"/>
    <inertia ixx="0.0004893447900749665" ixy="-9.162992041314064e-06" ixz="3.260397026410497e-05" iyy="0.0006151042459896073" iyz="4.1782859988479925e-05" izz="0.00016656385625372916"/>
  </inertial>
  <visual>
    <origin rpy="0 0 0" xyz="0.020612 0.403351 0.02737"/>
    <geometry>
      <mesh filename="meshes/puru_returns_Component1_v21.stl" scale="0.001 0.001 0.001"/>
    </geometry>
    <material name="silver"/>
    <material/>
  </visual>
  <collision>
    <origin rpy="0 0 0" xyz="0.020612 0.403351 0.02737"/>
    <geometry>
      <mesh filename="meshes/puru_returns_Component1_v21.stl" scale="0.001 0.001 0.001"/>
    </geometry>
  </collision>
</link>

<link name="testing_Component2_Copy_v11Component241">
  <inertial>
    <origin rpy="0 0 0" xyz="0.01160696009246041 -0.02121142605938714 -0.023255091004357763"/>
    <mass value="0.08459587295154185"/>
    <inertia ixx="7.338981053277988e-05" ixy="1.7503980058993852e-06" ixz="-1.594223482162467e-06" iyy="4.716794606117423e-05" iyz="6.933879975922624e-06" izz="3.60646584516254e-05"/>
  </inertial>
  <visual>
    <origin rpy="0 0 0" xyz="0.01639 0.374833 -0.007814"/>
    <geometry>
      <mesh filename="meshes/testing_Component2_Copy_v11Component241.stl" scale="0.001 0.001 0.001"/>
    </geometry>
    <material name="silver"/>
    <material/>
  </visual>
  <collision>
    <origin rpy="0 0 0" xyz="0.01639 0.374833 -0.007814"/>
    <geometry>
      <mesh filename="meshes/testing_Component2_Copy_v11Component241.stl" scale="0.001 0.001 0.001"/>
    </geometry>
  </collision>
</link>

<link name="darwin_SP0-5_Dfaut_v1_81">
  <inertial>
    <origin rpy="0 0 0" xyz="-0.001499872472012026 -1.8643558677422511e-07 2.114932754592857e-07"/>
    <mass value="0.00403268334001312"/>
    <inertia ixx="1.8171957172168334e-07" ixy="2.710505431213761e-20" ixz="-1.7736075822116998e-19" iyy="9.40413563103198e-08" iyz="-1.852884572118782e-22" izz="9.404135767055984e-08"/>
  </inertial>
  <visual>
    <origin rpy="0 0 0" xyz="-0.129856 0.189597 -0.000226"/>
    <geometry>
      <mesh filename="meshes/darwin_SP0-5_Dfaut_v1_81.stl" scale="0.001 0.001 0.001"/>
    </geometry>
    <material name="silver"/>
    <material/>
  </visual>
  <collision>
    <origin rpy="0 0 0" xyz="-0.129856 0.189597 -0.000226"/>
    <geometry>
      <mesh filename="meshes/darwin_SP0-5_Dfaut_v1_81.stl" scale="0.001 0.001 0.001"/>
    </geometry>
  </collision>
</link>

<link name="New_comp_mirror_v11">
  <inertial>
    <origin rpy="0 0 0" xyz="-0.027127870061510503 -0.007395510584347981 0.025150287826569827"/>
    <mass value="0.09272661140293512"/>
    <inertia ixx="5.041279014412429e-05" ixy="-1.3253400060317302e-06" ixz="5.403142625535069e-06" iyy="5.750978567617957e-05" iyz="1.0330125334118102e-05" izz="4.5813057631747915e-05"/>
  </inertial>
  <visual>
    <origin rpy="0 0 0" xyz="-0.133619 0.183725 0.038944"/>
    <geometry>
      <mesh filename="meshes/New_comp_mirror_v11.stl" scale="0.001 0.001 0.001"/>
    </geometry>
    <material name="silver"/>
    <material/>
  </visual>
  <collision>
    <origin rpy="0 0 0" xyz="-0.133619 0.183725 0.038944"/>
    <geometry>
      <mesh filename="meshes/New_comp_mirror_v11.stl" scale="0.001 0.001 0.001"/>
    </geometry>
  </collision>
</link>

<link name="servo_v1_81">
  <inertial>
    <origin rpy="0 0 0" xyz="-0.01129654845435854 -0.024198227206637002 0.00587023955355454"/>
    <mass value="0.25257832542625036"/>
    <inertia ixx="4.409603015031495e-05" ixy="-5.055183367472585e-07" ixz="-2.7633792843773704e-12" iyy="4.062675597017772e-05" iyz="-4.393122326455548e-11" izz="6.81815359492681e-05"/>
  </inertial>
  <visual>
    <origin rpy="0 0 0" xyz="-0.115926 0.175375 0.005644"/>
    <geometry>
      <mesh filename="meshes/servo_v1_81.stl" scale="0.001 0.001 0.001"/>
    </geometry>
    <material name="silver"/>
    <material/>
  </visual>
  <collision>
    <origin rpy="0 0 0" xyz="-0.115926 0.175375 0.005644"/>
    <geometry>
      <mesh filename="meshes/servo_v1_81.stl" scale="0.001 0.001 0.001"/>
    </geometry>
  </collision>
</link>

<link name="darwin_SP0-5_Dfaut_v1_91">
  <inertial>
    <origin rpy="0 0 0" xyz="-0.32751587247201375 -0.307618775192456 0.2433360311745527"/>
    <mass value="0.00403268334001312"/>
    <inertia ixx="1.8171957172173755e-07" ixy="2.168404344971009e-19" ixz="-6.617444900424221e-23" iyy="9.404135767058694e-08" iyz="-1.3234889800848443e-22" izz="9.40413563103198e-08"/>
  </inertial>
  <visual>
    <origin rpy="0 0 0" xyz="-0.455872 -0.008213 0.243151"/>
    <geometry>
      <mesh filename="meshes/darwin_SP0-5_Dfaut_v1_91.stl" scale="0.001 0.001 0.001"/>
    </geometry>
    <material name="silver"/>
    <material/>
  </visual>
  <collision>
    <origin rpy="0 0 0" xyz="-0.455872 -0.008213 0.243151"/>
    <geometry>
      <mesh filename="meshes/darwin_SP0-5_Dfaut_v1_91.stl" scale="0.001 0.001 0.001"/>
    </geometry>
  </collision>
</link>

<link name="servo_v1_91">
  <inertial>
    <origin rpy="0 0 0" xyz="-0.3231325484543601 -0.009790815963280408 -0.12685594076539397"/>
    <mass value="0.25257832542625036"/>
    <inertia ixx="4.4096030150316684e-05" ixy="-5.055183367481259e-07" ixz="-2.763379245413855e-12" iyy="4.062675597017772e-05" iyz="-4.393122326455548e-11" izz="6.81815359492681e-05"/>
  </inertial>
  <visual>
    <origin rpy="0 0 0" xyz="-0.427762 0.299591 -0.127041"/>
    <geometry>
      <mesh filename="meshes/servo_v1_91.stl" scale="0.001 0.001 0.001"/>
    </geometry>
    <material name="silver"/>
    <material/>
  </visual>
  <collision>
    <origin rpy="0 0 0" xyz="-0.427762 0.299591 -0.127041"/>
    <geometry>
      <mesh filename="meshes/servo_v1_91.stl" scale="0.001 0.001 0.001"/>
    </geometry>
  </collision>
</link>

<link name="puru_returns_Component3_Copy_mirror_v11">
  <inertial>
    <origin rpy="0 0 0" xyz="-0.01123501747540645 -0.05805164811902869 0.007072890973456966"/>
    <mass value="0.1851062904404302"/>
    <inertia ixx="0.00012398617807460321" ixy="1.4689737333854584e-05" ixz="8.602094731067869e-07" iyy="5.9023273681404424e-05" iyz="-7.755929246310063e-06" izz="0.000166772563396686"/>
  </inertial>
  <visual>
    <origin rpy="0 0 0" xyz="-0.113546 0.285184 0.005685"/>
    <geometry>
      <mesh filename="meshes/puru_returns_Component3_Copy_mirror_v11.stl" scale="0.001 0.001 0.001"/>
    </geometry>
    <material name="silver"/>
    <material/>
  </visual>
  <collision>
    <origin rpy="0 0 0" xyz="-0.113546 0.285184 0.005685"/>
    <geometry>
      <mesh filename="meshes/puru_returns_Component3_Copy_mirror_v11.stl" scale="0.001 0.001 0.001"/>
    </geometry>
  </collision>
</link>

<link name="darwin_SP0-5_Dfaut_v1_111">
  <inertial>
    <origin rpy="0 0 0" xyz="0.7741718559400748 0.030810224807544473 -0.12940146180666873"/>
    <mass value="0.00403268334001312"/>
    <inertia ixx="1.8171957172179176e-07" ixy="1.8973538018496328e-19" ixz="2.6469779601696886e-23" iyy="9.404135767057339e-08" iyz="-1.5881867761018131e-22" izz="9.4041356310374e-08"/>
  </inertial>
  <visual>
    <origin rpy="0 0 0" xyz="0.64627 0.440216 -0.129591"/>
    <geometry>
      <mesh filename="meshes/darwin_SP0-5_Dfaut_v1_111.stl" scale="0.001 0.001 0.001"/>
    </geometry>
    <material name="silver"/>
    <material/>
  </visual>
  <collision>
    <origin rpy="0 0 0" xyz="0.64627 0.440216 -0.129591"/>
    <geometry>
      <mesh filename="meshes/darwin_SP0-5_Dfaut_v1_111.stl" scale="0.001 0.001 0.001"/>
    </geometry>
  </collision>
</link>

<link name="servo_v1_101">
  <inertial>
    <origin rpy="0 0 0" xyz="-0.025226820042271336 0.009976265578820809 -4.898667222452452e-07"/>
    <mass value="0.25257832542625036"/>
    <inertia ixx="4.4096030150313215e-05" ixy="5.055183367481259e-07" ixz="2.763379230167262e-12" iyy="4.0626755970177286e-05" iyz="-4.3931223262861415e-11" izz="6.818153594926463e-05"/>
  </inertial>
  <visual>
    <origin rpy="0 0 0" xyz="-0.126402 0.409406 -0.00019"/>
    <geometry>
      <mesh filename="meshes/servo_v1_101.stl" scale="0.001 0.001 0.001"/>
    </geometry>
    <material name="silver"/>
    <material/>
  </visual>
  <collision>
    <origin rpy="0 0 0" xyz="-0.126402 0.409406 -0.00019"/>
    <geometry>
      <mesh filename="meshes/servo_v1_101.stl" scale="0.001 0.001 0.001"/>
    </geometry>
  </collision>
</link>

<link name="testing_Component2__mirror_v11">
  <inertial>
    <origin rpy="0 0 0" xyz="-0.011606734217913972 -0.021211640035304957 -0.023255059732441862"/>
    <mass value="0.08459586965507518"/>
    <inertia ixx="7.338980948064407e-05" ixy="-1.7503980014681696e-06" ixz="1.5942234281329272e-06" iyy="4.716794569811474e-05" iyz="6.9338799705697014e-06" izz="3.6064657152940285e-05"/>
  </inertial>
  <visual>
    <origin rpy="0 0 0" xyz="-0.110092 0.373113 -0.007271"/>
    <geometry>
      <mesh filename="meshes/testing_Component2__mirror_v11.stl" scale="0.001 0.001 0.001"/>
    </geometry>
    <material name="silver"/>
    <material/>
  </visual>
  <collision>
    <origin rpy="0 0 0" xyz="-0.110092 0.373113 -0.007271"/>
    <geometry>
      <mesh filename="meshes/testing_Component2__mirror_v11.stl" scale="0.001 0.001 0.001"/>
    </geometry>
  </collision>
</link>

<link name="darwin_SP0-5_Dfaut_v1_121">
  <inertial>
    <origin rpy="0 0 0" xyz="0.04728785594030022 0.04260378684413246 -0.42624443036391074"/>
    <mass value="0.00403268334001312"/>
    <inertia ixx="9.404135767072247e-08" ixy="-2.710505431213761e-20" ixz="-1.7702988597614877e-19" iyy="9.404135631031302e-08" iyz="-3.3881317890172014e-21" izz="1.8171957172168334e-07"/>
  </inertial>
  <visual>
    <origin rpy="0 0 0" xyz="-0.052804 0.450105 -0.413141"/>
    <geometry>
      <mesh filename="meshes/darwin_SP0-5_Dfaut_v1_121.stl" scale="0.001 0.001 0.001"/>
    </geometry>
    <material name="silver"/>
    <material/>
  </visual>
  <collision>
    <origin rpy="0 0 0" xyz="-0.052804 0.450105 -0.413141"/>
    <geometry>
      <mesh filename="meshes/darwin_SP0-5_Dfaut_v1_121.stl" scale="0.001 0.001 0.001"/>
    </geometry>
  </collision>
</link>

<link name="New_Component_v2_11Component311">
  <inertial>
    <origin rpy="0 0 0" xyz="-0.024752698113984145 -0.058250149595918205 -1.818488759332577e-05"/>
    <mass value="0.12057690606604259"/>
    <inertia ixx="9.059967566988052e-05" ixy="-3.3675587649472857e-07" ixz="5.060593851470395e-11" iyy="5.50834704258589e-05" iyz="-1.2191716247732408e-07" izz="0.0001364974799907409"/>
  </inertial>
  <visual>
    <origin rpy="0 0 0" xyz="-0.129856 0.183597 -0.000226"/>
    <geometry>
      <mesh filename="meshes/New_Component_v2_11Component311.stl" scale="0.001 0.001 0.001"/>
    </geometry>
    <material name="silver"/>
    <material/>
  </visual>
  <collision>
    <origin rpy="0 0 0" xyz="-0.129856 0.183597 -0.000226"/>
    <geometry>
      <mesh filename="meshes/New_Component_v2_11Component311.stl" scale="0.001 0.001 0.001"/>
    </geometry>
  </collision>
</link>

<link name="servo_v1_111">
  <inertial>
    <origin rpy="0 0 0" xyz="0.024579896711124205 0.10009175878407861 -0.4322281063462574"/>
    <mass value="0.25257832542625036"/>
    <inertia ixx="4.0626755970184225e-05" ixy="-4.393121977308567e-11" ixz="5.055183367483427e-07" iyy="6.818153594926853e-05" iyz="2.763379369080665e-12" izz="4.4096030150313215e-05"/>
  </inertial>
  <visual>
    <origin rpy="0 0 0" xyz="-0.085488 0.507593 -0.394398"/>
    <geometry>
      <mesh filename="meshes/servo_v1_111.stl" scale="0.001 0.001 0.001"/>
    </geometry>
    <material name="silver"/>
    <material/>
  </visual>
  <collision>
    <origin rpy="0 0 0" xyz="-0.085488 0.507593 -0.394398"/>
    <geometry>
      <mesh filename="meshes/servo_v1_111.stl" scale="0.001 0.001 0.001"/>
    </geometry>
  </collision>
</link>

<link name="puru_returns_Component1_mirror_v11">
  <inertial>
    <origin rpy="0 0 0" xyz="-0.019640844103188837 -0.029623117097055063 0.00617570392138404"/>
    <mass value="0.3521119210080811"/>
    <inertia ixx="0.0004893447900749665" ixy="9.162992041324147e-06" ixz="-3.2603970264115443e-05" iyy="0.0006151042459895933" iyz="4.178285998847949e-05" izz="0.00016656385625371528"/>
  </inertial>
  <visual>
    <origin rpy="0 0 0" xyz="-0.13467 0.401631 0.028913"/>
    <geometry>
      <mesh filename="meshes/puru_returns_Component1_mirror_v11.stl" scale="0.001 0.001 0.001"/>
    </geometry>
    <material name="silver"/>
    <material/>
  </visual>
  <collision>
    <origin rpy="0 0 0" xyz="-0.13467 0.401631 0.028913"/>
    <geometry>
      <mesh filename="meshes/puru_returns_Component1_mirror_v11.stl" scale="0.001 0.001 0.001"/>
    </geometry>
  </collision>
</link>

<joint name="Rigid5" type="fixed">
  <origin rpy="0 0 0" xyz="-0.006829 -0.137658 0.035397"/>
  <parent link="base_link"/>
  <child link="servo_v11"/>
</joint>

<joint name="Rigid6" type="fixed">
  <origin rpy="0 0 0" xyz="0.104916 -0.137658 0.035397"/>
  <parent link="base_link"/>
  <child link="servo_v1_11"/>
</joint>

<joint name="Rev7" type="continuous">
  <origin rpy="0 0 0" xyz="-0.005875 -0.01631 -0.034578"/>
  <parent link="servo_v1_11"/>
  <child link="darwin_SP0-5_Dfaut_v1_11"/>
  <axis xyz="-0.0 -1.0 0.0"/>
</joint>
<transmission name="Rev7_tran">
  <type>transmission_interface/SimpleTransmission</type>
  <joint name="Rev7">
    <hardwareInterface>PositionJointInterface</hardwareInterface>
  </joint>
  <actuator name="Rev7_actr">
    <hardwareInterface>PositionJointInterface</hardwareInterface>
    <mechanicalReduction>1</mechanicalReduction>
  </actuator>
</transmission>

<joint name="Rev8" type="continuous">
  <origin rpy="0 0 0" xyz="0.00587 -0.01631 -0.034578"/>
  <parent link="servo_v11"/>
  <child link="darwin_SP0-5_Dfaut_v11"/>
  <axis xyz="-0.0 -1.0 0.0"/>
</joint>
<transmission name="Rev8_tran">
  <type>transmission_interface/SimpleTransmission</type>
  <joint name="Rev8">
    <hardwareInterface>PositionJointInterface</hardwareInterface>
  </joint>
  <actuator name="Rev8_actr">
    <hardwareInterface>PositionJointInterface</hardwareInterface>
    <mechanicalReduction>1</mechanicalReduction>
  </actuator>
</transmission>

<joint name="Rigid9" type="fixed">
  <origin rpy="0 0 0" xyz="0.006 0.0 0.0"/>
  <parent link="darwin_SP0-5_Dfaut_v11"/>
  <child link="puru_returns_Component6_v31"/>
</joint>

<joint name="Rigid10" type="fixed">
  <origin rpy="0 0 0" xyz="0.006 0.0 0.0"/>
  <parent link="darwin_SP0-5_Dfaut_v1_11"/>
  <child link="puru_returns_Component6_v3_11"/>
</joint>

<joint name="Rigid11" type="fixed">
  <origin rpy="0 0 0" xyz="0.0 -0.035632 -0.056073"/>
  <parent link="puru_returns_Component6_v31"/>
  <child link="darwin_SP0-5_Dfaut_v1_21"/>
</joint>

<joint name="Rev12" type="continuous">
  <origin rpy="0 0 0" xyz="-0.006959 0.052255 -0.1881"/>
  <parent link="darwin_SP0-5_Dfaut_v1_21"/>
  <child link="servo_v1_21"/>
  <axis xyz="-0.0 0.0 1.0"/>
</joint>
<transmission name="Rev12_tran">
  <type>transmission_interface/SimpleTransmission</type>
  <joint name="Rev12">
    <hardwareInterface>PositionJointInterface</hardwareInterface>
  </joint>
  <actuator name="Rev12_actr">
    <hardwareInterface>PositionJointInterface</hardwareInterface>
    <mechanicalReduction>1</mechanicalReduction>
  </actuator>
</transmission>

<joint name="Rigid13" type="fixed">
  <origin rpy="0 0 0" xyz="0.0 -0.035632 -0.056073"/>
  <parent link="puru_returns_Component6_v3_11"/>
  <child link="darwin_SP0-5_Dfaut_v1_31"/>
</joint>

<joint name="Rev14" type="continuous">
  <origin rpy="0 0 0" xyz="0.093041 0.052255 -0.1881"/>
  <parent link="darwin_SP0-5_Dfaut_v1_31"/>
  <child link="servo_v1_31"/>
  <axis xyz="-0.0 0.0 1.0"/>
</joint>
<transmission name="Rev14_tran">
  <type>transmission_interface/SimpleTransmission</type>
  <joint name="Rev14">
    <hardwareInterface>PositionJointInterface</hardwareInterface>
  </joint>
  <actuator name="Rev14_actr">
    <hardwareInterface>PositionJointInterface</hardwareInterface>
    <mechanicalReduction>1</mechanicalReduction>
  </actuator>
</transmission>

<joint name="Rigid16" type="fixed">
  <origin rpy="0 0 0" xyz="-0.033619 -0.046385 0.20616"/>
  <parent link="servo_v1_21"/>
  <child link="New_comp_v31"/>
</joint>

<joint name="Rigid17" type="fixed">
  <origin rpy="0 0 0" xyz="0.017693 0.008351 0.045045"/>
  <parent link="New_comp_v31"/>
  <child link="servo_v1_41"/>
</joint>

<joint name="Rev18" type="continuous">
  <origin rpy="0 0 0" xyz="-0.000399 0.009753 0.183731"/>
  <parent link="servo_v1_41"/>
  <child link="darwin_SP0-5_Dfaut_v1_41"/>
  <axis xyz="-1.0 0.0 -0.0"/>
</joint>
<transmission name="Rev18_tran">
  <type>transmission_interface/SimpleTransmission</type>
  <joint name="Rev18">
    <hardwareInterface>PositionJointInterface</hardwareInterface>
  </joint>
  <actuator name="Rev18_actr">
    <hardwareInterface>PositionJointInterface</hardwareInterface>
    <mechanicalReduction>1</mechanicalReduction>
  </actuator>
</transmission>

<joint name="Rigid19" type="fixed">
  <origin rpy="0 0 0" xyz="-0.014911 -0.023976 -0.195601"/>
  <parent link="darwin_SP0-5_Dfaut_v1_41"/>
  <child link="New_Component_v21Component171"/>
</joint>

<joint name="Rigid20" type="fixed">
  <origin rpy="0 0 0" xyz="0.365635 -0.132869 0.039112"/>
  <parent link="New_Component_v21Component171"/>
  <child link="darwin_SP0-5_Dfaut_v1_51"/>
</joint>

<joint name="Rev21" type="continuous">
  <origin rpy="0 0 0" xyz="-0.064725 0.021121 -0.063307"/>
  <parent link="darwin_SP0-5_Dfaut_v1_51"/>
  <child link="servo_v1_51"/>
  <axis xyz="-1.0 0.0 -0.0"/>
</joint>
<transmission name="Rev21_tran">
  <type>transmission_interface/SimpleTransmission</type>
  <joint name="Rev21">
    <hardwareInterface>PositionJointInterface</hardwareInterface>
  </joint>
  <actuator name="Rev21_actr">
    <hardwareInterface>PositionJointInterface</hardwareInterface>
    <mechanicalReduction>1</mechanicalReduction>
  </actuator>
</transmission>

<joint name="Rigid22" type="fixed">
  <origin rpy="0 0 0" xyz="-0.2846 0.016162 0.036024"/>
  <parent link="servo_v1_51"/>
  <child link="puru_returns_Component3_Copy_v11"/>
</joint>

<joint name="Rigid23" type="fixed">
  <origin rpy="0 0 0" xyz="-0.015856 -0.118222 -0.00587"/>
  <parent link="puru_returns_Component3_Copy_v11"/>
  <child link="darwin_SP0-5_Dfaut_v1_61"/>
</joint>

<joint name="Rev24" type="continuous">
  <origin rpy="0 0 0" xyz="0.410911 -0.0357 0.001939"/>
  <parent link="darwin_SP0-5_Dfaut_v1_61"/>
  <child link="servo_v1_61"/>
  <axis xyz="-1.0 0.0 -0.0"/>
</joint>
<transmission name="Rev24_tran">
  <type>transmission_interface/SimpleTransmission</type>
  <joint name="Rev24">
    <hardwareInterface>PositionJointInterface</hardwareInterface>
  </joint>
  <actuator name="Rev24_actr">
    <hardwareInterface>PositionJointInterface</hardwareInterface>
    <mechanicalReduction>1</mechanicalReduction>
  </actuator>
</transmission>

<joint name="Rigid26" type="fixed">
  <origin rpy="0 0 0" xyz="0.009611 -0.076448 0.40759"/>
  <parent link="testing_Component2_Copy_v11Component241"/>
  <child link="darwin_SP0-5_Dfaut_v1_71"/>
</joint>

<joint name="Rev27" type="continuous">
  <origin rpy="0 0 0" xyz="-0.006 0.028 -0.018743"/>
  <parent link="darwin_SP0-5_Dfaut_v1_71"/>
  <child link="servo_v1_71"/>
  <axis xyz="-0.0 0.0 -1.0"/>
</joint>
<transmission name="Rev27_tran">
  <type>transmission_interface/SimpleTransmission</type>
  <joint name="Rev27">
    <hardwareInterface>PositionJointInterface</hardwareInterface>
  </joint>
  <actuator name="Rev27_actr">
    <hardwareInterface>PositionJointInterface</hardwareInterface>
    <mechanicalReduction>1</mechanicalReduction>
  </actuator>
</transmission>

<joint name="Rigid28" type="fixed">
  <origin rpy="0 0 0" xyz="-0.007833 0.01993 -0.424031"/>
  <parent link="servo_v1_71"/>
  <child link="puru_returns_Component1_v21"/>
</joint>

<joint name="Rigid29" type="fixed">
  <origin rpy="0 0 0" xyz="-0.394601 0.064277 0.003935"/>
  <parent link="servo_v1_61"/>
  <child link="testing_Component2_Copy_v11Component241"/>
</joint>

<joint name="Rev33" type="continuous">
  <origin rpy="0 0 0" xyz="0.01393 -0.014222 0.00587"/>
  <parent link="servo_v1_81"/>
  <child link="darwin_SP0-5_Dfaut_v1_81"/>
  <axis xyz="1.0 -0.0 0.0"/>
</joint>
<transmission name="Rev33_tran">
  <type>transmission_interface/SimpleTransmission</type>
  <joint name="Rev33">
    <hardwareInterface>PositionJointInterface</hardwareInterface>
  </joint>
  <actuator name="Rev33_actr">
    <hardwareInterface>PositionJointInterface</hardwareInterface>
    <mechanicalReduction>1</mechanicalReduction>
  </actuator>
</transmission>

<joint name="Rigid35" type="fixed">
  <origin rpy="0 0 0" xyz="-0.064463 -0.04638 0.20441"/>
  <parent link="servo_v1_31"/>
  <child link="New_comp_mirror_v11"/>
</joint>

<joint name="Rigid36" type="fixed">
  <origin rpy="0 0 0" xyz="-0.017693 0.00835 0.0333"/>
  <parent link="New_comp_mirror_v11"/>
  <child link="servo_v1_81"/>
</joint>

<joint name="Rigid38" type="fixed">
  <origin rpy="0 0 0" xyz="0.326016 0.19181 -0.243377"/>
  <parent link="New_Component_v2_11Component311"/>
  <child link="darwin_SP0-5_Dfaut_v1_91"/>
</joint>

<joint name="Rev39" type="continuous">
  <origin rpy="0 0 0" xyz="-0.02811 -0.307804 0.370192"/>
  <parent link="darwin_SP0-5_Dfaut_v1_91"/>
  <child link="servo_v1_91"/>
  <axis xyz="-1.0 0.0 0.0"/>
</joint>
<transmission name="Rev39_tran">
  <type>transmission_interface/SimpleTransmission</type>
  <joint name="Rev39">
    <hardwareInterface>PositionJointInterface</hardwareInterface>
  </joint>
  <actuator name="Rev39_actr">
    <hardwareInterface>PositionJointInterface</hardwareInterface>
    <mechanicalReduction>1</mechanicalReduction>
  </actuator>
</transmission>

<joint name="Rigid40" type="fixed">
  <origin rpy="0 0 0" xyz="-0.314216 0.014407 -0.132726"/>
  <parent link="servo_v1_91"/>
  <child link="puru_returns_Component3_Copy_mirror_v11"/>
</joint>

<joint name="Rigid41" type="fixed">
  <origin rpy="0 0 0" xyz="-0.759816 -0.155032 0.135276"/>
  <parent link="puru_returns_Component3_Copy_mirror_v11"/>
  <child link="darwin_SP0-5_Dfaut_v1_111"/>
</joint>

<joint name="Rev42" type="continuous">
  <origin rpy="0 0 0" xyz="0.772672 0.03081 -0.129401"/>
  <parent link="darwin_SP0-5_Dfaut_v1_111"/>
  <child link="servo_v1_101"/>
  <axis xyz="-1.0 0.0 -0.0"/>
</joint>
<transmission name="Rev42_tran">
  <type>transmission_interface/SimpleTransmission</type>
  <joint name="Rev42">
    <hardwareInterface>PositionJointInterface</hardwareInterface>
  </joint>
  <actuator name="Rev42_actr">
    <hardwareInterface>PositionJointInterface</hardwareInterface>
    <mechanicalReduction>1</mechanicalReduction>
  </actuator>
</transmission>

<joint name="Rigid43" type="fixed">
  <origin rpy="0 0 0" xyz="-0.01631 0.036293 0.007081"/>
  <parent link="servo_v1_101"/>
  <child link="testing_Component2__mirror_v11"/>
</joint>

<joint name="Rigid44" type="fixed">
  <origin rpy="0 0 0" xyz="-0.057288 -0.076992 0.40587"/>
  <parent link="testing_Component2__mirror_v11"/>
  <child link="darwin_SP0-5_Dfaut_v1_121"/>
</joint>

<joint name="Rigid45" type="fixed">
  <origin rpy="0 0 0" xyz="0.0 0.006 0.0"/>
  <parent link="darwin_SP0-5_Dfaut_v1_81"/>
  <child link="New_Component_v2_11Component311"/>
</joint>

<joint name="Rev46" type="continuous">
  <origin rpy="0 0 0" xyz="0.032684 -0.057488 -0.018743"/>
  <parent link="darwin_SP0-5_Dfaut_v1_121"/>
  <child link="servo_v1_111"/>
  <axis xyz="-0.0 0.0 -1.0"/>
</joint>
<transmission name="Rev46_tran">
  <type>transmission_interface/SimpleTransmission</type>
  <joint name="Rev46">
    <hardwareInterface>PositionJointInterface</hardwareInterface>
  </joint>
  <actuator name="Rev46_actr">
    <hardwareInterface>PositionJointInterface</hardwareInterface>
    <mechanicalReduction>1</mechanicalReduction>
  </actuator>
</transmission>

<joint name="Rigid47" type="fixed">
  <origin rpy="0 0 0" xyz="0.049182 0.105962 -0.423311"/>
  <parent link="servo_v1_111"/>
  <child link="puru_returns_Component1_mirror_v11"/>
</joint>

</robot>
