<?xml version="1.0" ?>
<robot name="COM">

<material name="silver">
  <color rgba="0.700 0.700 0.700 1.000"/>
</material>

<link name="base_link">
  <inertial>
    <origin rpy="0 0 0" xyz="0.049426872993293534 -0.05856788394564916 0.014469977603933622"/>
    <mass value="6.087495213581755"/>
    <inertia ixx="0.01478590284265107" ixy="-0.00011943604355989582" ixz="4.0528118599583024e-05" iyy="0.027826181686333544" iyz="0.0006996436301212553" izz="0.03368371018690616"/>
  </inertial>
  <visual>
    <origin rpy="0 0 0" xyz="0 0 0"/>
    <geometry>
      <mesh filename="meshes/base_link.stl" scale="0.001 0.001 0.001"/>
    </geometry>
    <material name="silver"/>
    <material/>
  </visual>
  <collision>
    <origin rpy="0 0 0" xyz="0 0 0"/>
    <geometry>
      <mesh filename="meshes/base_link.stl" scale="0.001 0.001 0.001"/>
    </geometry>
  </collision>
</link>

<link name="darwin_SP0-5_Dfaut_v1_11">
  <inertial>
    <origin rpy="0 0 0" xyz="-3.801167810790762e-07 0.0014997351662962843 -7.013422203064335e-08"/>
    <mass value="0.00403268334001312"/>
    <inertia ixx="9.40413563103198e-08" ixy="0.0" ixz="1.6940658945086007e-21" iyy="1.8171957172162913e-07" iyz="-1.8295911660692887e-19" izz="9.404135767055984e-08"/>
  </inertial>
  <visual>
    <origin rpy="0 0 0" xyz="-0.099046 0.153968 -0.021175"/>
    <geometry>
      <mesh filename="meshes/darwin_SP0-5_Dfaut_v1_11.stl" scale="0.001 0.001 0.001"/>
    </geometry>
    <material name="silver"/>
    <material/>
  </visual>
  <collision>
    <origin rpy="0 0 0" xyz="-0.099046 0.153968 -0.021175"/>
    <geometry>
      <mesh filename="meshes/darwin_SP0-5_Dfaut_v1_11.stl" scale="0.001 0.001 0.001"/>
    </geometry>
  </collision>
</link>

<link name="darwin_SP0-5_Dfaut_v11">
  <inertial>
    <origin rpy="0 0 0" xyz="-3.8011678041597816e-07 0.0014997329912126434 -7.013422255106039e-08"/>
    <mass value="0.00403268334001312"/>
    <inertia ixx="9.40413563103198e-08" ixy="0.0" ixz="1.852884572118782e-22" iyy="1.8171957172164184e-07" iyz="-1.7787691892340307e-19" izz="9.404135767061405e-08"/>
  </inertial>
  <visual>
    <origin rpy="0 0 0" xyz="0.000954 0.153968 -0.021175"/>
    <geometry>
      <mesh filename="meshes/darwin_SP0-5_Dfaut_v11.stl" scale="0.001 0.001 0.001"/>
    </geometry>
    <material name="silver"/>
    <material/>
  </visual>
  <collision>
    <origin rpy="0 0 0" xyz="0.000954 0.153968 -0.021175"/>
    <geometry>
      <mesh filename="meshes/darwin_SP0-5_Dfaut_v11.stl" scale="0.001 0.001 0.001"/>
    </geometry>
  </collision>
</link>

<link name="darwin_SP0-5_Dfaut_v1_21">
  <inertial>
    <origin rpy="0 0 0" xyz="-0.006000380116780482 2.337932812623844e-07 0.0015001048247358859"/>
    <mass value="0.00403268334001312"/>
    <inertia ixx="9.404135631029269e-08" ixy="-2.117582368135751e-22" ixz="0.0" iyy="9.404135767058864e-08" iyz="-1.7957098481791167e-19" izz="1.8171957172168334e-07"/>
  </inertial>
  <visual>
    <origin rpy="0 0 0" xyz="-0.005046 0.1896 0.034899"/>
    <geometry>
      <mesh filename="meshes/darwin_SP0-5_Dfaut_v1_21.stl" scale="0.001 0.001 0.001"/>
    </geometry>
    <material name="silver"/>
    <material/>
  </visual>
  <collision>
    <origin rpy="0 0 0" xyz="-0.005046 0.1896 0.034899"/>
    <geometry>
      <mesh filename="meshes/darwin_SP0-5_Dfaut_v1_21.stl" scale="0.001 0.001 0.001"/>
    </geometry>
  </collision>
</link>

<link name="servo_v1_21">
  <inertial>
    <origin rpy="0 0 0" xyz="-0.009021322027019007 -0.03189873611224242 0.21507652859351006"/>
    <mass value="0.2525811539773393"/>
    <inertia ixx="4.0628291142298656e-05" ixy="-8.622513412905736e-11" ixz="5.060799491813541e-07" iyy="6.818318895881881e-05" iyz="3.2885922956159275e-10" izz="4.40963468847852e-05"/>
  </inertial>
  <visual>
    <origin rpy="0 0 0" xyz="0.001909 0.157701 0.222999"/>
    <geometry>
      <mesh filename="meshes/servo_v1_21.stl" scale="0.001 0.001 0.001"/>
    </geometry>
    <material name="silver"/>
    <material/>
  </visual>
  <collision>
    <origin rpy="0 0 0" xyz="0.001909 0.157701 0.222999"/>
    <geometry>
      <mesh filename="meshes/servo_v1_21.stl" scale="0.001 0.001 0.001"/>
    </geometry>
  </collision>
</link>

<link name="darwin_SP0-5_Dfaut_v1_31">
  <inertial>
    <origin rpy="0 0 0" xyz="-0.006000380116781057 2.359683649033606e-07 0.0015001048247363091"/>
    <mass value="0.00403268334001312"/>
    <inertia ixx="9.404135631026558e-08" ixy="0.0" ixz="0.0" iyy="9.404135767058694e-08" iyz="-1.7618285302889447e-19" izz="1.8171957172165624e-07"/>
  </inertial>
  <visual>
    <origin rpy="0 0 0" xyz="-0.105046 0.1896 0.034899"/>
    <geometry>
      <mesh filename="meshes/darwin_SP0-5_Dfaut_v1_31.stl" scale="0.001 0.001 0.001"/>
    </geometry>
    <material name="silver"/>
    <material/>
  </visual>
  <collision>
    <origin rpy="0 0 0" xyz="-0.105046 0.1896 0.034899"/>
    <geometry>
      <mesh filename="meshes/darwin_SP0-5_Dfaut_v1_31.stl" scale="0.001 0.001 0.001"/>
    </geometry>
  </collision>
</link>

<link name="servo_v1_31">
  <inertial>
    <origin rpy="0 0 0" xyz="-0.08906943820654246 -0.03189879412565988 0.21332652859351048"/>
    <mass value="0.2525811539773393"/>
    <inertia ixx="4.062829114230039e-05" ixy="-8.62251338037967e-11" ixz="-5.060799491814422e-07" iyy="6.818318895881852e-05" iyz="-3.288592298326433e-10" izz="4.40963468847852e-05"/>
  </inertial>
  <visual>
    <origin rpy="0 0 0" xyz="-0.198091 0.157701 0.222999"/>
    <geometry>
      <mesh filename="meshes/servo_v1_31.stl" scale="0.001 0.001 0.001"/>
    </geometry>
    <material name="silver"/>
    <material/>
  </visual>
  <collision>
    <origin rpy="0 0 0" xyz="-0.198091 0.157701 0.222999"/>
    <geometry>
      <mesh filename="meshes/servo_v1_31.stl" scale="0.001 0.001 0.001"/>
    </geometry>
  </collision>
</link>

<link name="New_comp_v31">
  <inertial>
    <origin rpy="0 0 0" xyz="0.02712760280916824 -0.00739501977821197 0.025150828643777975"/>
    <mass value="0.09272661140293506"/>
    <inertia ixx="5.0412790144149875e-05" ixy="1.3253400060312694e-06" ixz="-5.403142625515372e-06" iyy="5.7509785676170845e-05" iyz="1.0330125334125529e-05" izz="4.581305763172146e-05"/>
  </inertial>
  <visual>
    <origin rpy="0 0 0" xyz="0.035532 0.18373 0.016839"/>
    <geometry>
      <mesh filename="meshes/New_comp_v31.stl" scale="0.001 0.001 0.001"/>
    </geometry>
    <material name="silver"/>
    <material/>
  </visual>
  <collision>
    <origin rpy="0 0 0" xyz="0.035532 0.18373 0.016839"/>
    <geometry>
      <mesh filename="meshes/New_comp_v31.stl" scale="0.001 0.001 0.001"/>
    </geometry>
  </collision>
</link>

<link name="servo_v1_41">
  <inertial>
    <origin rpy="0 0 0" xyz="0.008916028988444513 -0.024198637539689233 -0.005869710576260234"/>
    <mass value="0.2525811539773393"/>
    <inertia ixx="4.409634688478346e-05" ixy="5.060799491812796e-07" ixz="3.288592297038943e-10" iyy="4.062829114230028e-05" iyz="-8.622513467115844e-11" izz="6.818318895881678e-05"/>
  </inertial>
  <visual>
    <origin rpy="0 0 0" xyz="0.017839 0.175379 -0.028206"/>
    <geometry>
      <mesh filename="meshes/servo_v1_41.stl" scale="0.001 0.001 0.001"/>
    </geometry>
    <material name="silver"/>
    <material/>
  </visual>
  <collision>
    <origin rpy="0 0 0" xyz="0.017839 0.175379 -0.028206"/>
    <geometry>
      <mesh filename="meshes/servo_v1_41.stl" scale="0.001 0.001 0.001"/>
    </geometry>
  </collision>
</link>

<link name="darwin_SP0-5_Dfaut_v1_41">
  <inertial>
    <origin rpy="0 0 0" xyz="-0.03376639478032952 -0.023971695629450396 -0.18960174067028493"/>
    <mass value="0.00403268334001312"/>
    <inertia ixx="1.8171957172165624e-07" ixy="0.0" ixz="-1.7745340244977592e-19" iyy="9.404135631031302e-08" iyz="0.0" izz="9.404135767061405e-08"/>
  </inertial>
  <visual>
    <origin rpy="0 0 0" xyz="-0.002117 0.16563 -0.211938"/>
    <geometry>
      <mesh filename="meshes/darwin_SP0-5_Dfaut_v1_41.stl" scale="0.001 0.001 0.001"/>
    </geometry>
    <material name="silver"/>
    <material/>
  </visual>
  <collision>
    <origin rpy="0 0 0" xyz="-0.002117 0.16563 -0.211938"/>
    <geometry>
      <mesh filename="meshes/darwin_SP0-5_Dfaut_v1_41.stl" scale="0.001 0.001 0.001"/>
    </geometry>
  </collision>
</link>

<link name="New_Component_v21Component171">
  <inertial>
    <origin rpy="0 0 0" xyz="0.022246779577698293 -0.05224965878978241 0.005981862948394902"/>
    <mass value="0.12057690606604259"/>
    <inertia ixx="9.059967566987966e-05" ixy="-3.3675587649521646e-07" ixz="5.060593844609428e-11" iyy="5.5083470425859116e-05" iyz="-1.2191716247753753e-07" izz="0.0001364974799907331"/>
  </inertial>
  <visual>
    <origin rpy="0 0 0" xyz="0.033149 0.189602 -0.016336"/>
    <geometry>
      <mesh filename="meshes/New_Component_v21Component171.stl" scale="0.001 0.001 0.001"/>
    </geometry>
    <material name="silver"/>
    <material/>
  </visual>
  <collision>
    <origin rpy="0 0 0" xyz="0.033149 0.189602 -0.016336"/>
    <geometry>
      <mesh filename="meshes/New_Component_v21Component171.stl" scale="0.001 0.001 0.001"/>
    </geometry>
  </collision>
</link>

<link name="darwin_SP0-5_Dfaut_v1_51">
  <inertial>
    <origin rpy="0 0 0" xyz="-0.36413539478033113 0.0027047156136809636 -0.03314892098945918"/>
    <mass value="0.00403268334001312"/>
    <inertia ixx="1.8171957172162913e-07" ixy="1.7618285302889447e-19" ixz="4.235164736271502e-22" iyy="9.404135767058779e-08" iyz="-3.3881317890172014e-21" izz="9.404135631026558e-08"/>
  </inertial>
  <visual>
    <origin rpy="0 0 0" xyz="-0.332486 0.302115 -0.055444"/>
    <geometry>
      <mesh filename="meshes/darwin_SP0-5_Dfaut_v1_51.stl" scale="0.001 0.001 0.001"/>
    </geometry>
    <material name="silver"/>
    <material/>
  </visual>
  <collision>
    <origin rpy="0 0 0" xyz="-0.332486 0.302115 -0.055444"/>
    <geometry>
      <mesh filename="meshes/darwin_SP0-5_Dfaut_v1_51.stl" scale="0.001 0.001 0.001"/>
    </geometry>
  </collision>
</link>

<link name="servo_v1_51">
  <inertial>
    <origin rpy="0 0 0" xyz="-0.27568397101155717 0.01231877370366774 0.030149109104791173"/>
    <mass value="0.2525811539773393"/>
    <inertia ixx="4.409634688478173e-05" ixy="5.060799491812254e-07" ixz="3.288592297174468e-10" iyy="4.062829114230023e-05" iyz="-8.622513445431801e-11" izz="6.818318895881331e-05"/>
  </inertial>
  <visual>
    <origin rpy="0 0 0" xyz="-0.267761 0.321705 0.007854"/>
    <geometry>
      <mesh filename="meshes/servo_v1_51.stl" scale="0.001 0.001 0.001"/>
    </geometry>
    <material name="silver"/>
    <material/>
  </visual>
  <collision>
    <origin rpy="0 0 0" xyz="-0.267761 0.321705 0.007854"/>
    <geometry>
      <mesh filename="meshes/servo_v1_51.stl" scale="0.001 0.001 0.001"/>
    </geometry>
  </collision>
</link>

<link name="puru_returns_Component3_Copy_v11">
  <inertial>
    <origin rpy="0 0 0" xyz="0.011234750223060534 -0.058052157312893204 -0.004671568209335092"/>
    <mass value="0.18510629044043106"/>
    <inertia ixx="0.00012398617807460321" ixy="-1.4689737333858054e-05" ixz="-8.602094731073629e-07" iyy="5.9023273681416905e-05" iyz="-7.755929246309589e-06" izz="0.0001667725633965854"/>
  </inertial>
  <visual>
    <origin rpy="0 0 0" xyz="0.016839 0.285188 -0.028165"/>
    <geometry>
      <mesh filename="meshes/puru_returns_Component3_Copy_v11.stl" scale="0.001 0.001 0.001"/>
    </geometry>
    <material name="silver"/>
    <material/>
  </visual>
  <collision>
    <origin rpy="0 0 0" xyz="0.016839 0.285188 -0.028165"/>
    <geometry>
      <mesh filename="meshes/puru_returns_Component3_Copy_v11.stl" scale="0.001 0.001 0.001"/>
    </geometry>
  </collision>
</link>

<link name="darwin_SP0-5_Dfaut_v1_61">
  <inertial>
    <origin rpy="0 0 0" xyz="0.001499876807576947 -0.006000284386093402 7.901076473290636e-08"/>
    <mass value="0.00403268334001312"/>
    <inertia ixx="1.8171957172157492e-07" ixy="0.0" ixz="-1.7702988597614877e-19" iyy="9.404135631031302e-08" iyz="0.0" izz="9.404135767061405e-08"/>
  </inertial>
  <visual>
    <origin rpy="0 0 0" xyz="0.032695 0.40341 -0.022295"/>
    <geometry>
      <mesh filename="meshes/darwin_SP0-5_Dfaut_v1_61.stl" scale="0.001 0.001 0.001"/>
    </geometry>
    <material name="silver"/>
    <material/>
  </visual>
  <collision>
    <origin rpy="0 0 0" xyz="0.032695 0.40341 -0.022295"/>
    <geometry>
      <mesh filename="meshes/darwin_SP0-5_Dfaut_v1_61.stl" scale="0.001 0.001 0.001"/>
    </geometry>
  </collision>
</link>

<link name="servo_v1_61">
  <inertial>
    <origin rpy="0 0 0" xyz="-0.3856836994236488 0.03967065752414539 -0.022294951083711257"/>
    <mass value="0.2525811539773393"/>
    <inertia ixx="4.409634688479214e-05" ixy="-5.060799491815506e-07" ixz="-3.2885922975132813e-10" iyy="4.0628291142300336e-05" iyz="-8.622513423747757e-11" izz="6.818318895882025e-05"/>
  </inertial>
  <visual>
    <origin rpy="0 0 0" xyz="-0.378215 0.439105 -0.04459"/>
    <geometry>
      <mesh filename="meshes/servo_v1_61.stl" scale="0.001 0.001 0.001"/>
    </geometry>
    <material name="silver"/>
    <material/>
  </visual>
  <collision>
    <origin rpy="0 0 0" xyz="-0.378215 0.439105 -0.04459"/>
    <geometry>
      <mesh filename="meshes/servo_v1_61.stl" scale="0.001 0.001 0.001"/>
    </geometry>
  </collision>
</link>

<link name="darwin_SP0-5_Dfaut_v1_71">
  <inertial>
    <origin rpy="0 0 0" xyz="0.00038487680757666454 0.021705000834289667 -0.4279639209894614"/>
    <mass value="0.00403268334001312"/>
    <inertia ixx="9.404135631015716e-08" ixy="0.0" ixz="1.2970192004831474e-21" iyy="9.40413576705879e-08" iyz="-1.7787691892340307e-19" izz="1.817195717214665e-07"/>
  </inertial>
  <visual>
    <origin rpy="0 0 0" xyz="0.00677 0.430926 -0.435759"/>
    <geometry>
      <mesh filename="meshes/darwin_SP0-5_Dfaut_v1_71.stl" scale="0.001 0.001 0.001"/>
    </geometry>
    <material name="silver"/>
    <material/>
  </visual>
  <collision>
    <origin rpy="0 0 0" xyz="0.00677 0.430926 -0.435759"/>
    <geometry>
      <mesh filename="meshes/darwin_SP0-5_Dfaut_v1_71.stl" scale="0.001 0.001 0.001"/>
    </geometry>
  </collision>
</link>

<link name="servo_v1_71">
  <inertial>
    <origin rpy="0 0 0" xyz="0.016360818717814467 -0.006294969071685641 -0.4329473447582359"/>
    <mass value="0.2525811539773393"/>
    <inertia ixx="4.0628291142298656e-05" ixy="8.622513450852812e-11" ixz="5.060799491814541e-07" iyy="6.818318895881896e-05" iyz="-3.288592291279119e-10" izz="4.40963468847852e-05"/>
  </inertial>
  <visual>
    <origin rpy="0 0 0" xyz="0.01277 0.402926 -0.417016"/>
    <geometry>
      <mesh filename="meshes/servo_v1_71.stl" scale="0.001 0.001 0.001"/>
    </geometry>
    <material name="silver"/>
    <material/>
  </visual>
  <collision>
    <origin rpy="0 0 0" xyz="0.01277 0.402926 -0.417016"/>
    <geometry>
      <mesh filename="meshes/servo_v1_71.stl" scale="0.001 0.001 0.001"/>
    </geometry>
  </collision>
</link>

<link name="puru_returns_Component1_v21">
  <inertial>
    <origin rpy="0 0 0" xyz="0.019640117668046936 -0.029622903107123566 0.008676213295834543"/>
    <mass value="0.3521119210080813"/>
    <inertia ixx="0.0004893447900749665" ixy="-9.162992041314037e-06" ixz="3.260397026410497e-05" iyy="0.0006151042459896072" iyz="4.178285998848036e-05" izz="0.00016656385625371528"/>
  </inertial>
  <visual>
    <origin rpy="0 0 0" xyz="0.020607 0.403351 0.007015"/>
    <geometry>
      <mesh filename="meshes/puru_returns_Component1_v21.stl" scale="0.001 0.001 0.001"/>
    </geometry>
    <material name="silver"/>
    <material/>
  </visual>
  <collision>
    <origin rpy="0 0 0" xyz="0.020607 0.403351 0.007015"/>
    <geometry>
      <mesh filename="meshes/puru_returns_Component1_v21.stl" scale="0.001 0.001 0.001"/>
    </geometry>
  </collision>
</link>

<link name="testing_Component2_Copy_v11Component241">
  <inertial>
    <origin rpy="0 0 0" xyz="0.011606467111240991 -0.021211426059386862 -0.023255550187149806"/>
    <mass value="0.08459587295154185"/>
    <inertia ixx="7.33898105327764e-05" ixy="1.7503980058993852e-06" ixz="-1.594223482162464e-06" iyy="4.7167946061174216e-05" iyz="6.93387997592257e-06" izz="3.606465845162714e-05"/>
  </inertial>
  <visual>
    <origin rpy="0 0 0" xyz="0.016385 0.374833 -0.02817"/>
    <geometry>
      <mesh filename="meshes/testing_Component2_Copy_v11Component241.stl" scale="0.001 0.001 0.001"/>
    </geometry>
    <material name="silver"/>
    <material/>
  </visual>
  <collision>
    <origin rpy="0 0 0" xyz="0.016385 0.374833 -0.02817"/>
    <geometry>
      <mesh filename="meshes/testing_Component2_Copy_v11Component241.stl" scale="0.001 0.001 0.001"/>
    </geometry>
  </collision>
</link>

<link name="darwin_SP0-5_Dfaut_v1_81">
  <inertial>
    <origin rpy="0 0 0" xyz="-0.0015003654532318444 -1.8643558619135803e-07 -2.476895162237258e-07"/>
    <mass value="0.00403268334001312"/>
    <inertia ixx="1.8171957172162913e-07" ixy="0.0" ixz="-1.7448878713438587e-19" iyy="9.404135631030624e-08" iyz="3.3881317890172014e-21" izz="9.404135767047852e-08"/>
  </inertial>
  <visual>
    <origin rpy="0 0 0" xyz="-0.129861 0.189597 -0.020582"/>
    <geometry>
      <mesh filename="meshes/darwin_SP0-5_Dfaut_v1_81.stl" scale="0.001 0.001 0.001"/>
    </geometry>
    <material name="silver"/>
    <material/>
  </visual>
  <collision>
    <origin rpy="0 0 0" xyz="-0.129861 0.189597 -0.020582"/>
    <geometry>
      <mesh filename="meshes/darwin_SP0-5_Dfaut_v1_81.stl" scale="0.001 0.001 0.001"/>
    </geometry>
  </collision>
</link>

<link name="New_comp_mirror_v11">
  <inertial>
    <origin rpy="0 0 0" xyz="-0.027127363042730376 -0.007395510584347703 0.02515082864377812"/>
    <mass value="0.09272661140293512"/>
    <inertia ixx="5.0412790144126456e-05" ixy="-1.3253400060315133e-06" ixz="5.403142625535069e-06" iyy="5.750978567617892e-05" iyz="1.0330125334118007e-05" izz="4.5813057631740976e-05"/>
  </inertial>
  <visual>
    <origin rpy="0 0 0" xyz="-0.133623 0.183725 0.018589"/>
    <geometry>
      <mesh filename="meshes/New_comp_mirror_v11.stl" scale="0.001 0.001 0.001"/>
    </geometry>
    <material name="silver"/>
    <material/>
  </visual>
  <collision>
    <origin rpy="0 0 0" xyz="-0.133623 0.183725 0.018589"/>
    <geometry>
      <mesh filename="meshes/New_comp_mirror_v11.stl" scale="0.001 0.001 0.001"/>
    </geometry>
  </collision>
</link>

<link name="servo_v1_81">
  <inertial>
    <origin rpy="0 0 0" xyz="-0.011296789222006262 -0.024198128345824715 0.005869722216458744"/>
    <mass value="0.2525811539773393"/>
    <inertia ixx="4.409634688478346e-05" ixy="-5.060799491826348e-07" ixz="3.2885922967001296e-10" iyy="4.0628291142300824e-05" iyz="8.62251338037967e-11" izz="6.818318895881505e-05"/>
  </inertial>
  <visual>
    <origin rpy="0 0 0" xyz="-0.115931 0.175375 -0.014712"/>
    <geometry>
      <mesh filename="meshes/servo_v1_81.stl" scale="0.001 0.001 0.001"/>
    </geometry>
    <material name="silver"/>
    <material/>
  </visual>
  <collision>
    <origin rpy="0 0 0" xyz="-0.115931 0.175375 -0.014712"/>
    <geometry>
      <mesh filename="meshes/servo_v1_81.stl" scale="0.001 0.001 0.001"/>
    </geometry>
  </collision>
</link>

<link name="darwin_SP0-5_Dfaut_v1_91">
  <inertial>
    <origin rpy="0 0 0" xyz="-0.3275163654532336 -0.32797477519245566 0.24334057199176104"/>
    <mass value="0.00403268334001312"/>
    <inertia ixx="1.8171957172168334e-07" ixy="1.8973538018496328e-19" ixz="0.0" iyy="9.404135767057339e-08" iyz="0.0" izz="9.404135631026558e-08"/>
  </inertial>
  <visual>
    <origin rpy="0 0 0" xyz="-0.455877 -0.028569 0.2228"/>
    <geometry>
      <mesh filename="meshes/darwin_SP0-5_Dfaut_v1_91.stl" scale="0.001 0.001 0.001"/>
    </geometry>
    <material name="silver"/>
    <material/>
  </visual>
  <collision>
    <origin rpy="0 0 0" xyz="-0.455877 -0.028569 0.2228"/>
    <geometry>
      <mesh filename="meshes/darwin_SP0-5_Dfaut_v1_91.stl" scale="0.001 0.001 0.001"/>
    </geometry>
  </collision>
</link>

<link name="servo_v1_91">
  <inertial>
    <origin rpy="0 0 0" xyz="-0.32313178922200786 0.010564282897531752 -0.12686045810248975"/>
    <mass value="0.2525811539773393"/>
    <inertia ixx="4.409634688477826e-05" ixy="-5.060799491817675e-07" ixz="3.288592297784332e-10" iyy="4.062829114230039e-05" iyz="8.622513358695627e-11" izz="6.818318895881678e-05"/>
  </inertial>
  <visual>
    <origin rpy="0 0 0" xyz="-0.427766 0.319946 -0.147401"/>
    <geometry>
      <mesh filename="meshes/servo_v1_91.stl" scale="0.001 0.001 0.001"/>
    </geometry>
    <material name="silver"/>
    <material/>
  </visual>
  <collision>
    <origin rpy="0 0 0" xyz="-0.427766 0.319946 -0.147401"/>
    <geometry>
      <mesh filename="meshes/servo_v1_91.stl" scale="0.001 0.001 0.001"/>
    </geometry>
  </collision>
</link>

<link name="puru_returns_Component3_Copy_mirror_v11">
  <inertial>
    <origin rpy="0 0 0" xyz="-0.011235510456626366 -0.058051648119028465 0.007072431790665291"/>
    <mass value="0.1851062904404302"/>
    <inertia ixx="0.00012398617807459975" ixy="1.4689737333855452e-05" ixz="8.602094731067632e-07" iyy="5.9023273681409194e-05" iyz="-7.755929246310023e-06" izz="0.00016677256339666865"/>
  </inertial>
  <visual>
    <origin rpy="0 0 0" xyz="-0.113551 0.285184 -0.014671"/>
    <geometry>
      <mesh filename="meshes/puru_returns_Component3_Copy_mirror_v11.stl" scale="0.001 0.001 0.001"/>
    </geometry>
    <material name="silver"/>
    <material/>
  </visual>
  <collision>
    <origin rpy="0 0 0" xyz="-0.113551 0.285184 -0.014671"/>
    <geometry>
      <mesh filename="meshes/puru_returns_Component3_Copy_mirror_v11.stl" scale="0.001 0.001 0.001"/>
    </geometry>
  </collision>
</link>

<link name="darwin_SP0-5_Dfaut_v1_111">
  <inertial>
    <origin rpy="0 0 0" xyz="0.7741723629588548 0.010455224807544905 -0.12940592098946038"/>
    <mass value="0.00403268334001312"/>
    <inertia ixx="1.8171957172168334e-07" ixy="1.6263032587282567e-19" ixz="0.0" iyy="9.404135767057339e-08" iyz="0.0" izz="9.4041356310374e-08"/>
  </inertial>
  <visual>
    <origin rpy="0 0 0" xyz="0.646266 0.419861 -0.149951"/>
    <geometry>
      <mesh filename="meshes/darwin_SP0-5_Dfaut_v1_111.stl" scale="0.001 0.001 0.001"/>
    </geometry>
    <material name="silver"/>
    <material/>
  </visual>
  <collision>
    <origin rpy="0 0 0" xyz="0.646266 0.419861 -0.149951"/>
    <geometry>
      <mesh filename="meshes/darwin_SP0-5_Dfaut_v1_111.stl" scale="0.001 0.001 0.001"/>
    </geometry>
  </collision>
</link>

<link name="servo_v1_101">
  <inertial>
    <origin rpy="0 0 0" xyz="-0.025226060809919 0.00997616671800916 1.0910479022671615e-07"/>
    <mass value="0.2525811539773393"/>
    <inertia ixx="4.409634688477826e-05" ixy="5.060799491800327e-07" ixz="-3.288592297784332e-10" iyy="4.062829114229952e-05" iyz="8.62251338037967e-11" izz="6.818318895882719e-05"/>
  </inertial>
  <visual>
    <origin rpy="0 0 0" xyz="-0.126406 0.409406 -0.020545"/>
    <geometry>
      <mesh filename="meshes/servo_v1_101.stl" scale="0.001 0.001 0.001"/>
    </geometry>
    <material name="silver"/>
    <material/>
  </visual>
  <collision>
    <origin rpy="0 0 0" xyz="-0.126406 0.409406 -0.020545"/>
    <geometry>
      <mesh filename="meshes/servo_v1_101.stl" scale="0.001 0.001 0.001"/>
    </geometry>
  </collision>
</link>

<link name="testing_Component2__mirror_v11">
  <inertial>
    <origin rpy="0 0 0" xyz="-0.011606227199133928 -0.021211640035304957 -0.023255518915233538"/>
    <mass value="0.08459586965507518"/>
    <inertia ixx="7.33898094806458e-05" ixy="-1.7503980014681696e-06" ixz="1.5942234281329746e-06" iyy="4.716794569811539e-05" iyz="6.9338799705697014e-06" izz="3.606465715294202e-05"/>
  </inertial>
  <visual>
    <origin rpy="0 0 0" xyz="-0.110096 0.373113 -0.027627"/>
    <geometry>
      <mesh filename="meshes/testing_Component2__mirror_v11.stl" scale="0.001 0.001 0.001"/>
    </geometry>
    <material name="silver"/>
    <material/>
  </visual>
  <collision>
    <origin rpy="0 0 0" xyz="-0.110096 0.373113 -0.027627"/>
    <geometry>
      <mesh filename="meshes/testing_Component2__mirror_v11.stl" scale="0.001 0.001 0.001"/>
    </geometry>
  </collision>
</link>

<link name="darwin_SP0-5_Dfaut_v1_121">
  <inertial>
    <origin rpy="0 0 0" xyz="0.047283362959080324 0.022247786844133033 -0.4262448895467025"/>
    <mass value="0.00403268334001312"/>
    <inertia ixx="9.404135767061405e-08" ixy="0.0" ixz="-1.7575933655526732e-19" iyy="9.40413563103198e-08" iyz="0.0" izz="1.8171957172168334e-07"/>
  </inertial>
  <visual>
    <origin rpy="0 0 0" xyz="-0.052813 0.429749 -0.433497"/>
    <geometry>
      <mesh filename="meshes/darwin_SP0-5_Dfaut_v1_121.stl" scale="0.001 0.001 0.001"/>
    </geometry>
    <material name="silver"/>
    <material/>
  </visual>
  <collision>
    <origin rpy="0 0 0" xyz="-0.052813 0.429749 -0.433497"/>
    <geometry>
      <mesh filename="meshes/darwin_SP0-5_Dfaut_v1_121.stl" scale="0.001 0.001 0.001"/>
    </geometry>
  </collision>
</link>

<link name="New_Component_v2_11Component311">
  <inertial>
    <origin rpy="0 0 0" xyz="-0.02475319109520406 -0.05825014959591793 -1.864407038499813e-05"/>
    <mass value="0.12057690606604259"/>
    <inertia ixx="9.059967566987879e-05" ixy="-3.3675587649559593e-07" ixz="5.0605938493528124e-11" iyy="5.5083470425859116e-05" iyz="-1.219171624773207e-07" izz="0.00013649747999073744"/>
  </inertial>
  <visual>
    <origin rpy="0 0 0" xyz="-0.129861 0.183597 -0.020582"/>
    <geometry>
      <mesh filename="meshes/New_Component_v2_11Component311.stl" scale="0.001 0.001 0.001"/>
    </geometry>
    <material name="silver"/>
    <material/>
  </visual>
  <collision>
    <origin rpy="0 0 0" xyz="-0.129861 0.183597 -0.020582"/>
    <geometry>
      <mesh filename="meshes/New_Component_v2_11Component311.stl" scale="0.001 0.001 0.001"/>
    </geometry>
  </collision>
</link>

<link name="servo_v1_111">
  <inertial>
    <origin rpy="0 0 0" xyz="0.0042243048690926155 0.10009681693838324 -0.43222731331547687"/>
    <mass value="0.2525811539773393"/>
    <inertia ixx="4.062829114229172e-05" ixy="8.622513293643497e-11" ixz="5.060799491814422e-07" iyy="6.818318895881895e-05" iyz="-3.2885922956159275e-10" izz="4.409634688477826e-05"/>
  </inertial>
  <visual>
    <origin rpy="0 0 0" xyz="-0.105848 0.507598 -0.414753"/>
    <geometry>
      <mesh filename="meshes/servo_v1_111.stl" scale="0.001 0.001 0.001"/>
    </geometry>
    <material name="silver"/>
    <material/>
  </visual>
  <collision>
    <origin rpy="0 0 0" xyz="-0.105848 0.507598 -0.414753"/>
    <geometry>
      <mesh filename="meshes/servo_v1_111.stl" scale="0.001 0.001 0.001"/>
    </geometry>
  </collision>
</link>

<link name="puru_returns_Component1_mirror_v11">
  <inertial>
    <origin rpy="0 0 0" xyz="-0.019640337084408696 -0.029623117097054508 0.006176244738592365"/>
    <mass value="0.3521119210080811"/>
    <inertia ixx="0.0004893447900749665" ixy="9.162992041324147e-06" ixz="-3.260397026411527e-05" iyy="0.0006151042459895941" iyz="4.178285998847895e-05" izz="0.0001665638562537014"/>
  </inertial>
  <visual>
    <origin rpy="0 0 0" xyz="-0.134674 0.401631 0.008558"/>
    <geometry>
      <mesh filename="meshes/puru_returns_Component1_mirror_v11.stl" scale="0.001 0.001 0.001"/>
    </geometry>
    <material name="silver"/>
    <material/>
  </visual>
  <collision>
    <origin rpy="0 0 0" xyz="-0.134674 0.401631 0.008558"/>
    <geometry>
      <mesh filename="meshes/puru_returns_Component1_mirror_v11.stl" scale="0.001 0.001 0.001"/>
    </geometry>
  </collision>
</link>

<link name="puru_returns_Component6_v31">
  <inertial>
    <origin rpy="0 0 0" xyz="-3.8011681072690987e-07 -0.01223905275395426 -0.024406931418907093"/>
    <mass value="0.04702613835521159"/>
    <inertia ixx="4.9731123091806186e-05" ixy="-1.9148873838577968e-17" ixz="1.0794958456723227e-17" iyy="4.3118777716014306e-05" iyz="1.9201203024805783e-06" izz="9.5104111718005e-06"/>
  </inertial>
  <visual>
    <origin rpy="0 0 0" xyz="0.000954 0.153968 -0.027175"/>
    <geometry>
      <mesh filename="meshes/puru_returns_Component6_v31.stl" scale="0.001 0.001 0.001"/>
    </geometry>
    <material name="silver"/>
    <material/>
  </visual>
  <collision>
    <origin rpy="0 0 0" xyz="0.000954 0.153968 -0.027175"/>
    <geometry>
      <mesh filename="meshes/puru_returns_Component6_v31.stl" scale="0.001 0.001 0.001"/>
    </geometry>
  </collision>
</link>

<link name="puru_returns_Component6_v3_11">
  <inertial>
    <origin rpy="0 0 0" xyz="-3.801168112632647e-07 -0.012239050578870758 -0.024406931418906555"/>
    <mass value="0.04702613835521159"/>
    <inertia ixx="4.97311230918064e-05" ixy="-1.919037845299343e-17" ixz="1.1047003698090585e-17" iyy="4.3118777716014286e-05" iyz="1.9201203024806393e-06" izz="9.510411171798116e-06"/>
  </inertial>
  <visual>
    <origin rpy="0 0 0" xyz="-0.099046 0.153968 -0.027175"/>
    <geometry>
      <mesh filename="meshes/puru_returns_Component6_v3_11.stl" scale="0.001 0.001 0.001"/>
    </geometry>
    <material name="silver"/>
    <material/>
  </visual>
  <collision>
    <origin rpy="0 0 0" xyz="-0.099046 0.153968 -0.027175"/>
    <geometry>
      <mesh filename="meshes/puru_returns_Component6_v3_11.stl" scale="0.001 0.001 0.001"/>
    </geometry>
  </collision>
</link>

<link name="servo_v11">
  <inertial>
    <origin rpy="0 0 0" xyz="0.005874649977469771 0.008916156759986665 0.02460198795576473"/>
    <mass value="0.2525811539773393"/>
    <inertia ixx="6.818318895881938e-05" ixy="3.2885922973099934e-10" ixz="-8.622513409771714e-11" iyy="4.409634688478469e-05" iyz="5.060799491813338e-07" izz="4.062829114230039e-05"/>
  </inertial>
  <visual>
    <origin rpy="0 0 0" xyz="0.006829 0.137658 0.013403"/>
    <geometry>
      <mesh filename="meshes/servo_v11.stl" scale="0.001 0.001 0.001"/>
    </geometry>
    <material name="silver"/>
    <material/>
  </visual>
  <collision>
    <origin rpy="0 0 0" xyz="0.006829 0.137658 0.013403"/>
    <geometry>
      <mesh filename="meshes/servo_v11.stl" scale="0.001 0.001 0.001"/>
    </geometry>
  </collision>
</link>

<link name="servo_v1_11">
  <inertial>
    <origin rpy="0 0 0" xyz="-0.005870408176834638 0.008916411148642445 0.024601889094953068"/>
    <mass value="0.25257832542625036"/>
    <inertia ixx="6.818153594926896e-05" ixy="-2.763379802761534e-12" ixz="4.393122291727197e-11" iyy="4.409603015031538e-05" iyz="5.055183367479632e-07" izz="4.062675597017989e-05"/>
  </inertial>
  <visual>
    <origin rpy="0 0 0" xyz="-0.104916 0.137658 0.013403"/>
    <geometry>
      <mesh filename="meshes/servo_v1_11.stl" scale="0.001 0.001 0.001"/>
    </geometry>
    <material name="silver"/>
    <material/>
  </visual>
  <collision>
    <origin rpy="0 0 0" xyz="-0.104916 0.137658 0.013403"/>
    <geometry>
      <mesh filename="meshes/servo_v1_11.stl" scale="0.001 0.001 0.001"/>
    </geometry>
  </collision>
</link>

<joint name="Rev7" type="continuous">
  <origin rpy="0 0 0" xyz="-0.00587 -0.01631 0.034578"/>
  <parent link="servo_v1_11"/>
  <child link="darwin_SP0-5_Dfaut_v1_11"/>
  <axis xyz="-0.0 -1.0 0.0"/>
</joint>
<transmission name="Rev7_tran">
  <type>transmission_interface/SimpleTransmission</type>
  <joint name="Rev7">
    <hardwareInterface>PositionJointInterface</hardwareInterface>
  </joint>
  <actuator name="Rev7_actr">
    <hardwareInterface>PositionJointInterface</hardwareInterface>
    <mechanicalReduction>1</mechanicalReduction>
  </actuator>
</transmission>

<joint name="Rev8" type="continuous">
  <origin rpy="0 0 0" xyz="0.005875 -0.01631 0.034578"/>
  <parent link="servo_v11"/>
  <child link="darwin_SP0-5_Dfaut_v11"/>
  <axis xyz="-0.0 -1.0 0.0"/>
</joint>
<transmission name="Rev8_tran">
  <type>transmission_interface/SimpleTransmission</type>
  <joint name="Rev8">
    <hardwareInterface>PositionJointInterface</hardwareInterface>
  </joint>
  <actuator name="Rev8_actr">
    <hardwareInterface>PositionJointInterface</hardwareInterface>
    <mechanicalReduction>1</mechanicalReduction>
  </actuator>
</transmission>

<joint name="Rigid11" type="fixed">
  <origin rpy="0 0 0" xyz="0.006 -0.035632 -0.062074"/>
  <parent link="puru_returns_Component6_v31"/>
  <child link="darwin_SP0-5_Dfaut_v1_21"/>
</joint>

<joint name="Rev12" type="continuous">
  <origin rpy="0 0 0" xyz="-0.006955 0.031899 -0.1881"/>
  <parent link="darwin_SP0-5_Dfaut_v1_21"/>
  <child link="servo_v1_21"/>
  <axis xyz="-0.0 0.0 1.0"/>
</joint>
<transmission name="Rev12_tran">
  <type>transmission_interface/SimpleTransmission</type>
  <joint name="Rev12">
    <hardwareInterface>PositionJointInterface</hardwareInterface>
  </joint>
  <actuator name="Rev12_actr">
    <hardwareInterface>PositionJointInterface</hardwareInterface>
    <mechanicalReduction>1</mechanicalReduction>
  </actuator>
</transmission>

<joint name="Rigid13" type="fixed">
  <origin rpy="0 0 0" xyz="0.006 -0.035632 -0.062074"/>
  <parent link="puru_returns_Component6_v3_11"/>
  <child link="darwin_SP0-5_Dfaut_v1_31"/>
</joint>

<joint name="Rev14" type="continuous">
  <origin rpy="0 0 0" xyz="0.093045 0.031899 -0.1881"/>
  <parent link="darwin_SP0-5_Dfaut_v1_31"/>
  <child link="servo_v1_31"/>
  <axis xyz="-0.0 0.0 1.0"/>
</joint>
<transmission name="Rev14_tran">
  <type>transmission_interface/SimpleTransmission</type>
  <joint name="Rev14">
    <hardwareInterface>PositionJointInterface</hardwareInterface>
  </joint>
  <actuator name="Rev14_actr">
    <hardwareInterface>PositionJointInterface</hardwareInterface>
    <mechanicalReduction>1</mechanicalReduction>
  </actuator>
</transmission>

<joint name="Rigid16" type="fixed">
  <origin rpy="0 0 0" xyz="-0.033623 -0.026029 0.20616"/>
  <parent link="servo_v1_21"/>
  <child link="New_comp_v31"/>
</joint>

<joint name="Rigid17" type="fixed">
  <origin rpy="0 0 0" xyz="0.017693 0.008351 0.045045"/>
  <parent link="New_comp_v31"/>
  <child link="servo_v1_41"/>
</joint>

<joint name="Rev18" type="continuous">
  <origin rpy="0 0 0" xyz="0.019956 0.009749 0.183732"/>
  <parent link="servo_v1_41"/>
  <child link="darwin_SP0-5_Dfaut_v1_41"/>
  <axis xyz="-1.0 0.0 -0.0"/>
</joint>
<transmission name="Rev18_tran">
  <type>transmission_interface/SimpleTransmission</type>
  <joint name="Rev18">
    <hardwareInterface>PositionJointInterface</hardwareInterface>
  </joint>
  <actuator name="Rev18_actr">
    <hardwareInterface>PositionJointInterface</hardwareInterface>
    <mechanicalReduction>1</mechanicalReduction>
  </actuator>
</transmission>

<joint name="Rigid19" type="fixed">
  <origin rpy="0 0 0" xyz="-0.035266 -0.023972 -0.195602"/>
  <parent link="darwin_SP0-5_Dfaut_v1_41"/>
  <child link="New_Component_v21Component171"/>
</joint>

<joint name="Rigid20" type="fixed">
  <origin rpy="0 0 0" xyz="0.365635 -0.112513 0.039108"/>
  <parent link="New_Component_v21Component171"/>
  <child link="darwin_SP0-5_Dfaut_v1_51"/>
</joint>

<joint name="Rev21" type="continuous">
  <origin rpy="0 0 0" xyz="-0.064725 -0.01959 -0.063298"/>
  <parent link="darwin_SP0-5_Dfaut_v1_51"/>
  <child link="servo_v1_51"/>
  <axis xyz="-1.0 0.0 -0.0"/>
</joint>
<transmission name="Rev21_tran">
  <type>transmission_interface/SimpleTransmission</type>
  <joint name="Rev21">
    <hardwareInterface>PositionJointInterface</hardwareInterface>
  </joint>
  <actuator name="Rev21_actr">
    <hardwareInterface>PositionJointInterface</hardwareInterface>
    <mechanicalReduction>1</mechanicalReduction>
  </actuator>
</transmission>

<joint name="Rigid22" type="fixed">
  <origin rpy="0 0 0" xyz="-0.2846 0.036517 0.036019"/>
  <parent link="servo_v1_51"/>
  <child link="puru_returns_Component3_Copy_v11"/>
</joint>

<joint name="Rigid23" type="fixed">
  <origin rpy="0 0 0" xyz="-0.015856 -0.118222 -0.00587"/>
  <parent link="puru_returns_Component3_Copy_v11"/>
  <child link="darwin_SP0-5_Dfaut_v1_61"/>
</joint>

<joint name="Rev24" type="continuous">
  <origin rpy="0 0 0" xyz="0.41091 -0.035695 0.022295"/>
  <parent link="darwin_SP0-5_Dfaut_v1_61"/>
  <child link="servo_v1_61"/>
  <axis xyz="-1.0 0.0 -0.0"/>
</joint>
<transmission name="Rev24_tran">
  <type>transmission_interface/SimpleTransmission</type>
  <joint name="Rev24">
    <hardwareInterface>PositionJointInterface</hardwareInterface>
  </joint>
  <actuator name="Rev24_actr">
    <hardwareInterface>PositionJointInterface</hardwareInterface>
    <mechanicalReduction>1</mechanicalReduction>
  </actuator>
</transmission>

<joint name="Rigid26" type="fixed">
  <origin rpy="0 0 0" xyz="0.009615 -0.056093 0.407589"/>
  <parent link="testing_Component2_Copy_v11Component241"/>
  <child link="darwin_SP0-5_Dfaut_v1_71"/>
</joint>

<joint name="Rev27" type="continuous">
  <origin rpy="0 0 0" xyz="-0.006 0.028 -0.018743"/>
  <parent link="darwin_SP0-5_Dfaut_v1_71"/>
  <child link="servo_v1_71"/>
  <axis xyz="-0.0 0.0 -1.0"/>
</joint>
<transmission name="Rev27_tran">
  <type>transmission_interface/SimpleTransmission</type>
  <joint name="Rev27">
    <hardwareInterface>PositionJointInterface</hardwareInterface>
  </joint>
  <actuator name="Rev27_actr">
    <hardwareInterface>PositionJointInterface</hardwareInterface>
    <mechanicalReduction>1</mechanicalReduction>
  </actuator>
</transmission>

<joint name="Rigid28" type="fixed">
  <origin rpy="0 0 0" xyz="-0.007837 -0.000425 -0.424031"/>
  <parent link="servo_v1_71"/>
  <child link="puru_returns_Component1_v21"/>
</joint>

<joint name="Rigid29" type="fixed">
  <origin rpy="0 0 0" xyz="-0.3946 0.064272 -0.01642"/>
  <parent link="servo_v1_61"/>
  <child link="testing_Component2_Copy_v11Component241"/>
</joint>

<joint name="Rev33" type="continuous">
  <origin rpy="0 0 0" xyz="0.01393 -0.014222 0.00587"/>
  <parent link="servo_v1_81"/>
  <child link="darwin_SP0-5_Dfaut_v1_81"/>
  <axis xyz="1.0 -0.0 0.0"/>
</joint>
<transmission name="Rev33_tran">
  <type>transmission_interface/SimpleTransmission</type>
  <joint name="Rev33">
    <hardwareInterface>PositionJointInterface</hardwareInterface>
  </joint>
  <actuator name="Rev33_actr">
    <hardwareInterface>PositionJointInterface</hardwareInterface>
    <mechanicalReduction>1</mechanicalReduction>
  </actuator>
</transmission>

<joint name="Rigid35" type="fixed">
  <origin rpy="0 0 0" xyz="-0.064468 -0.026024 0.20441"/>
  <parent link="servo_v1_31"/>
  <child link="New_comp_mirror_v11"/>
</joint>

<joint name="Rigid36" type="fixed">
  <origin rpy="0 0 0" xyz="-0.017692 0.00835 0.033301"/>
  <parent link="New_comp_mirror_v11"/>
  <child link="servo_v1_81"/>
</joint>

<joint name="Rigid38" type="fixed">
  <origin rpy="0 0 0" xyz="0.326016 0.212166 -0.243382"/>
  <parent link="New_Component_v2_11Component311"/>
  <child link="darwin_SP0-5_Dfaut_v1_91"/>
</joint>

<joint name="Rev39" type="continuous">
  <origin rpy="0 0 0" xyz="-0.028111 -0.348515 0.370201"/>
  <parent link="darwin_SP0-5_Dfaut_v1_91"/>
  <child link="servo_v1_91"/>
  <axis xyz="-1.0 0.0 0.0"/>
</joint>
<transmission name="Rev39_tran">
  <type>transmission_interface/SimpleTransmission</type>
  <joint name="Rev39">
    <hardwareInterface>PositionJointInterface</hardwareInterface>
  </joint>
  <actuator name="Rev39_actr">
    <hardwareInterface>PositionJointInterface</hardwareInterface>
    <mechanicalReduction>1</mechanicalReduction>
  </actuator>
</transmission>

<joint name="Rigid40" type="fixed">
  <origin rpy="0 0 0" xyz="-0.314215 0.034762 -0.13273"/>
  <parent link="servo_v1_91"/>
  <child link="puru_returns_Component3_Copy_mirror_v11"/>
</joint>

<joint name="Rigid41" type="fixed">
  <origin rpy="0 0 0" xyz="-0.759817 -0.134677 0.13528"/>
  <parent link="puru_returns_Component3_Copy_mirror_v11"/>
  <child link="darwin_SP0-5_Dfaut_v1_111"/>
</joint>

<joint name="Rev42" type="continuous">
  <origin rpy="0 0 0" xyz="0.772672 0.010455 -0.129406"/>
  <parent link="darwin_SP0-5_Dfaut_v1_111"/>
  <child link="servo_v1_101"/>
  <axis xyz="-1.0 0.0 -0.0"/>
</joint>
<transmission name="Rev42_tran">
  <type>transmission_interface/SimpleTransmission</type>
  <joint name="Rev42">
    <hardwareInterface>PositionJointInterface</hardwareInterface>
  </joint>
  <actuator name="Rev42_actr">
    <hardwareInterface>PositionJointInterface</hardwareInterface>
    <mechanicalReduction>1</mechanicalReduction>
  </actuator>
</transmission>

<joint name="Rigid43" type="fixed">
  <origin rpy="0 0 0" xyz="-0.01631 0.036293 0.007082"/>
  <parent link="servo_v1_101"/>
  <child link="testing_Component2__mirror_v11"/>
</joint>

<joint name="Rigid44" type="fixed">
  <origin rpy="0 0 0" xyz="-0.057283 -0.056636 0.40587"/>
  <parent link="testing_Component2__mirror_v11"/>
  <child link="darwin_SP0-5_Dfaut_v1_121"/>
</joint>

<joint name="Rigid45" type="fixed">
  <origin rpy="0 0 0" xyz="0.0 0.006 0.0"/>
  <parent link="darwin_SP0-5_Dfaut_v1_81"/>
  <child link="New_Component_v2_11Component311"/>
</joint>

<joint name="Rev46" type="continuous">
  <origin rpy="0 0 0" xyz="0.053035 -0.077849 -0.018744"/>
  <parent link="darwin_SP0-5_Dfaut_v1_121"/>
  <child link="servo_v1_111"/>
  <axis xyz="-0.0 0.0 -1.0"/>
</joint>
<transmission name="Rev46_tran">
  <type>transmission_interface/SimpleTransmission</type>
  <joint name="Rev46">
    <hardwareInterface>PositionJointInterface</hardwareInterface>
  </joint>
  <actuator name="Rev46_actr">
    <hardwareInterface>PositionJointInterface</hardwareInterface>
    <mechanicalReduction>1</mechanicalReduction>
  </actuator>
</transmission>

<joint name="Rigid47" type="fixed">
  <origin rpy="0 0 0" xyz="0.028826 0.105967 -0.423311"/>
  <parent link="servo_v1_111"/>
  <child link="puru_returns_Component1_mirror_v11"/>
</joint>

<joint name="Rigid53" type="fixed">
  <origin rpy="0 0 0" xyz="0.0 0.0 0.006"/>
  <parent link="darwin_SP0-5_Dfaut_v11"/>
  <child link="puru_returns_Component6_v31"/>
</joint>

<joint name="Rigid55" type="fixed">
  <origin rpy="0 0 0" xyz="0.0 0.0 0.006"/>
  <parent link="darwin_SP0-5_Dfaut_v1_11"/>
  <child link="puru_returns_Component6_v3_11"/>
</joint>

<joint name="Rigid56" type="fixed">
  <origin rpy="0 0 0" xyz="-0.006829 -0.137658 -0.013403"/>
  <parent link="base_link"/>
  <child link="servo_v11"/>
</joint>

<joint name="Rigid57" type="fixed">
  <origin rpy="0 0 0" xyz="0.104916 -0.137658 -0.013403"/>
  <parent link="base_link"/>
  <child link="servo_v1_11"/>
</joint>

</robot>
